Workbook
Name AllDependencies: _xlfn.VSTACK( _xlfn.HSTACK(tblDependencies[TargetID],tblDependencies[DependencyID]), _xlfn.HSTACK(tblQuestObjectives[QuestTargetID],tblQuestObjectives[ObjectiveID]) )
Name craftifactNames: #REF!
Name NormalizePrereqs: _xlfn.LAMBDA(_xlpm.txt,_xlfn.LET(_xlpm.t,_xlpm.txt,TRIM(SUBSTITUTE(SUBSTITUTE(SUBSTITUTE(SUBSTITUTE(SUBSTITUTE(_xlpm.t,CHAR(10),"|"),"<br/>","|"),"<br>","|"),"/","|"),"\","|"))))
Name Slicer_ChainAwareStatus: #N/A
Name Slicer_PlayerCompleted: #N/A
Name Slicer_PlayerPaid: #N/A
Name Slicer_TargetCompleted: #N/A
Name Slicer_TargetFunded: #N/A
Name Slicer_TargetType: #N/A
Name Slicer_TargetType1: #N/A

Sheet README

Sheet Player
A1: Setting | B1: Value | C1: PlayerStateID | D1: Description | E1: Note | G1: Player Type | H1: Active | K1: Active
A2: Character Level | B2: 1 | C2: state.character_level | D2: Current player level | E2: Only needs to be tracked until level 80 | K2: Passive
A3: Cartographer | B3: 0 | C3: state.character_cartographer | D3: Current cartographer level | E3: Only needs to be tracked until level 4
A4: Cooking | B4: 0 | C4: state.character_cooking | D4: Current Cooking level | E4: Only needs to be tracked until level 13

Sheet Dashboard
A1: Current Cost | I1: One Away | O1: Open Quests | S1: Pending actions | V1: Funded not Complete | Y1: Select Resource | Z1: ruby | AA1: {=_xlfn._xlws.FILTER( _xlfn.HSTACK( tblCostChecklist[DisplayName], tblCostChecklist[QuantityRequired], tblCostChecklist[TargetType] ), (tblCostChecklist[ResourceID]=$Z$1)* (tblCostChecklist[PlayerPaid]=FALSE)* (tblCostChecklist[TargetCompleted]="READY"), "No ready unpaid targets require this resource" )} -> Guild Lv 2 | AB1: 1 | AC1: BUILDING
A2: Target | B2: Type | C2: Sort | D2: Funded | E2: Remaining | F2: Cost Details | I2: Target | J2: Type | K2: Missing | L2: Cost Details | O2: Active Quest | P2: Outstanding Objective | S2: Action | T2: Unlocks | V2: {=_xlfn._xlws.FILTER( _xlfn.HSTACK( tblTargetStatus[DisplayName], tblTargetStatus[TargetType] ), (tblTargetStatus[Status]="READY")* (tblTargetStatus[TargetFunded]=TRUE), "No funded targets waiting for completion" )} -> No funded targets waiting for completion
A3: {=_xlfn.LET( _xlpm.data, _xlfn._xlws.FILTER( _xlfn.HSTACK( tblTargetStatus[DisplayName], tblTargetStatus[TargetType], tblTargetStatus[PlayerSort], tblTargetStatus[FundingPercent], tblTargetStatus[RemainingRequirements], tblTargetStatus[OutstandingResources] ), (tblTargetStatus[Status]="READY")* (tblTargetStatus[PlayerCompleted]=FALSE)* (tblTargetStatus[HasCost]=TRUE)* (tblTargetStatus[TargetFunded]=FALSE), "" ), IF( AND(ROWS(_xlpm.data)=1,INDEX(_xlpm.data,1,1)=""), "Nothing currently waiting for payment", _xlfn.SORTBY( _xlpm.data, _xlfn.CHOOSECOLS(_xlpm.data,3)="",1, _xlfn.CHOOSECOLS(_xlpm.data,3),1 ) ) )} -> Guild Lv 2 | B3: BUILDING | C3: 1 | D3: 0 | E3: 4 | F3: ruby: 1, coin: 50, wood: 50, stone: 50 | I3: {=_xlfn._xlws.FILTER( _xlfn.HSTACK( tblTargetStatus[DisplayName], tblTargetStatus[TargetType], tblTargetStatus[FirstMissingDependency], IFERROR(tblTargetStatus[Cost],"") ), (tblTargetStatus[ChainAwareStatus]="ONE AWAY")* (tblTargetStatus[PlayerCompleted]=FALSE)* (tblTargetStatus[completionmethod]="PLAYER"), "Nothing one step away" )} -> Alchemist's Hut Lv 1 | J3: BUILDING | K3: Character Level@6 | L3: 1 ruby,140 coin,70 wood,70 stone | O3: {=_xlfn._xlws.FILTER( _xlfn.HSTACK( tblQuestObjectives[QuestDisplayName], tblQuestObjectives[ObjectiveDisplayName] ), (tblQuestObjectives[Outstanding])* (tblQuestObjectives[activequest]), "No active quests" )} -> No active quests | S3: {=_xlfn._xlws.FILTER( _xlfn.HSTACK( tblTargetStatus[DisplayName], tblTargetStatus[PendingQuestAcceptances] ), (tblTargetStatus[Status]="READY")* (tblTargetStatus[TargetType]="STATE")* (tblTargetStatus[PlayerCompleted]=FALSE)* (tblTargetStatus[PendingQuestAcceptances]<>""), "No pending quest acceptance actions" )} -> No pending quest acceptance actions
I4: Bonsai Lv 1 | J4: BUILDING | K4: Character Level@21 | L4: 3 ruby,500 coin,500 plank,120 beans
I5: Bridge Lv 1 | J5: BUILDING | K5: Character Level@30 | L5: 4 ruby,1000 coin,400 beam,1000 plank,400 stone,100 steel
I6: Chicken Lv 1 | J6: BUILDING | K6: Character Level@15 | L6: 2 ruby,400 coin,400 beam,200 stone,20 wheat,10 thread,1 egg
I7: Dungeon Lv 1 | J7: BUILDING | K7: Character Level@10 | L7: 1 ruby,300 coin,200 wood,50 stone,100 steel,30 fan
I8: Field Lv 1 | J8: BUILDING | K8: Character Level@7 | L8: 1 ruby,200 coin,100 wood,20 chemicals
I9: Food Stall Lv 1 | J9: BUILDING | K9: Character Level@8 | L9: 1 ruby,300 coin,150 wood,150 stone,20 rice
I10: Furnace Lv 1 | J10: BUILDING | K10: Character Level@8 | L10: 1 ruby,200 coin,100 wood,100 stone
I11: Garden Lv 1 | J11: BUILDING | K11: Character Level@12 | L11: 1 ruby,400 coin,200 wood,100 stone
I12: Gong Lv 1 | J12: BUILDING | K12: Character Level@10 | L12: 3 ruby,200 coin,100 wood,50 stone,50 steel
I13: Guild Lv 3 | J13: BUILDING | K13: Guild Lv 2 | L13: 2 ruby,150 coin,300 beam,150 stone
I14: Lumber Lv 1 | J14: BUILDING | K14: Character Level@11 | L14: 1 ruby,300 coin,150 wood,150 stone
I15: Onsen Lv 1 | J15: BUILDING | K15: Character Level@20 | L15: 3 ruby,500 coin,500 plank,400 stone
... I22: Workshop Lv 1 | J22: BUILDING | K22: Character Level@2 | L22: 1 ruby,20 coin,10 wood,10 stone

Sheet Checklist
A1: TargetID | B1: DisplayName | C1: Successors | D1: TargetType | E1: ChainAwareStatus | F1: PlayerSort | G1: PlayerCompleted | H1: TargetFunded | I1: Recommended
A2: building.airship@1 | B2: =_xlfn.XLOOKUP(tblChecklist[[#This Row],[TargetID]],tblTargets[TargetID],tblTargets[DisplayName]) -> Airship Lv 1 | C2: =_xlfn.XLOOKUP( tblChecklist[[#This Row],[TargetID]], tblTargetStatus[TargetID], tblTargetStatus[successors], "" ) -> Airship Lv 2, Astrolabe, Cinema Projector, Dagger, Helmet, Safe, Telescope, Tetrachloroaurate, Festival Returns Accepted, Quest for Knowledge Chapter 5 Accepted | D2: BUILDING | E2: =_xlfn.XLOOKUP(tblChecklist[[#This Row],[TargetID]],tblTargetStatus[TargetID],tblTargetStatus[ChainAwareStatus],"") -> BLOCKED | F2: 44 | G2: FALSE | H2: =_xlfn.XLOOKUP(tblChecklist[[#This Row],[TargetID]],tblTargetStatus[TargetID],tblTargetStatus[TargetFunded],"") -> FALSE | I2: =IF( tblChecklist[[#This Row],[TargetType]]<>"BUILDING", "", IF( Player!$H$1="Active", _xlfn.XLOOKUP( tblChecklist[[#This Row],[TargetID]], tblrecommended[ActiveTargetID], tblrecommended[Order], "" ), _xlfn.XLOOKUP( tblChecklist[[#This Row],[TargetID]], tblrecommended[PassiveTargetID], tblrecommended[Order], "" ) ) ) -> 44
A3: building.airship@2 | B3: =_xlfn.XLOOKUP(tblChecklist[[#This Row],[TargetID]],tblTargets[TargetID],tblTargets[DisplayName]) -> Airship Lv 2 | C3: =_xlfn.XLOOKUP( tblChecklist[[#This Row],[TargetID]], tblTargetStatus[TargetID], tblTargetStatus[successors], "" ) -> Airship maxed | D3: BUILDING | E3: =_xlfn.XLOOKUP(tblChecklist[[#This Row],[TargetID]],tblTargetStatus[TargetID],tblTargetStatus[ChainAwareStatus],"") -> BLOCKED | F3: 45 | G3: FALSE | H3: =_xlfn.XLOOKUP(tblChecklist[[#This Row],[TargetID]],tblTargetStatus[TargetID],tblTargetStatus[TargetFunded],"") -> FALSE | I3: =IF( tblChecklist[[#This Row],[TargetType]]<>"BUILDING", "", IF( Player!$H$1="Active", _xlfn.XLOOKUP( tblChecklist[[#This Row],[TargetID]], tblrecommended[ActiveTargetID], tblrecommended[Order], "" ), _xlfn.XLOOKUP( tblChecklist[[#This Row],[TargetID]], tblrecommended[PassiveTargetID], tblrecommended[Order], "" ) ) ) -> 45
A4: building.alchemists_hut@1 | B4: =_xlfn.XLOOKUP(tblChecklist[[#This Row],[TargetID]],tblTargets[TargetID],tblTargets[DisplayName]) -> Alchemist's Hut Lv 1 | C4: =_xlfn.XLOOKUP( tblChecklist[[#This Row],[TargetID]], tblTargetStatus[TargetID], tblTargetStatus[successors], "" ) -> Alchemist's Hut Lv 2 | D4: BUILDING | E4: =_xlfn.XLOOKUP(tblChecklist[[#This Row],[TargetID]],tblTargetStatus[TargetID],tblTargetStatus[ChainAwareStatus],"") -> ONE AWAY | F4: 4 | G4: FALSE | H4: =_xlfn.XLOOKUP(tblChecklist[[#This Row],[TargetID]],tblTargetStatus[TargetID],tblTargetStatus[TargetFunded],"") -> FALSE | I4: =IF( tblChecklist[[#This Row],[TargetType]]<>"BUILDING", "", IF( Player!$H$1="Active", _xlfn.XLOOKUP( tblChecklist[[#This Row],[TargetID]], tblrecommended[ActiveTargetID], tblrecommended[Order], "" ), _xlfn.XLOOKUP( tblChecklist[[#This Row],[TargetID]], tblrecommended[PassiveTargetID], tblrecommended[Order], "" ) ) ) -> 4
A5: building.alchemists_hut@2 | B5: =_xlfn.XLOOKUP(tblChecklist[[#This Row],[TargetID]],tblTargets[TargetID],tblTargets[DisplayName]) -> Alchemist's Hut Lv 2 | C5: =_xlfn.XLOOKUP( tblChecklist[[#This Row],[TargetID]], tblTargetStatus[TargetID], tblTargetStatus[successors], "" ) -> Alchemist's Hut Lv 3 | D5: BUILDING | E5: =_xlfn.XLOOKUP(tblChecklist[[#This Row],[TargetID]],tblTargetStatus[TargetID],tblTargetStatus[ChainAwareStatus],"") -> BLOCKED | F5: 5 | G5: FALSE | H5: =_xlfn.XLOOKUP(tblChecklist[[#This Row],[TargetID]],tblTargetStatus[TargetID],tblTargetStatus[TargetFunded],"") -> FALSE | I5: =IF( tblChecklist[[#This Row],[TargetType]]<>"BUILDING", "", IF( Player!$H$1="Active", _xlfn.XLOOKUP( tblChecklist[[#This Row],[TargetID]], tblrecommended[ActiveTargetID], tblrecommended[Order], "" ), _xlfn.XLOOKUP( tblChecklist[[#This Row],[TargetID]], tblrecommended[PassiveTargetID], tblrecommended[Order], "" ) ) ) -> 5
A6: building.alchemists_hut@3 | B6: =_xlfn.XLOOKUP(tblChecklist[[#This Row],[TargetID]],tblTargets[TargetID],tblTargets[DisplayName]) -> Alchemist's Hut Lv 3 | C6: =_xlfn.XLOOKUP( tblChecklist[[#This Row],[TargetID]], tblTargetStatus[TargetID], tblTargetStatus[successors], "" ) -> Alchemist's Hut Lv 4 | D6: BUILDING | E6: =_xlfn.XLOOKUP(tblChecklist[[#This Row],[TargetID]],tblTargetStatus[TargetID],tblTargetStatus[ChainAwareStatus],"") -> BLOCKED | F6: 51 | G6: FALSE | H6: =_xlfn.XLOOKUP(tblChecklist[[#This Row],[TargetID]],tblTargetStatus[TargetID],tblTargetStatus[TargetFunded],"") -> FALSE | I6: =IF( tblChecklist[[#This Row],[TargetType]]<>"BUILDING", "", IF( Player!$H$1="Active", _xlfn.XLOOKUP( tblChecklist[[#This Row],[TargetID]], tblrecommended[ActiveTargetID], tblrecommended[Order], "" ), _xlfn.XLOOKUP( tblChecklist[[#This Row],[TargetID]], tblrecommended[PassiveTargetID], tblrecommended[Order], "" ) ) ) -> 51
A7: building.alchemists_hut@4 | B7: =_xlfn.XLOOKUP(tblChecklist[[#This Row],[TargetID]],tblTargets[TargetID],tblTargets[DisplayName]) -> Alchemist's Hut Lv 4 | C7: =_xlfn.XLOOKUP( tblChecklist[[#This Row],[TargetID]], tblTargetStatus[TargetID], tblTargetStatus[successors], "" ) -> Alchemist's Hut Lv 5 | D7: BUILDING | E7: =_xlfn.XLOOKUP(tblChecklist[[#This Row],[TargetID]],tblTargetStatus[TargetID],tblTargetStatus[ChainAwareStatus],"") -> BLOCKED | F7: 52 | G7: FALSE | H7: =_xlfn.XLOOKUP(tblChecklist[[#This Row],[TargetID]],tblTargetStatus[TargetID],tblTargetStatus[TargetFunded],"") -> FALSE | I7: =IF( tblChecklist[[#This Row],[TargetType]]<>"BUILDING", "", IF( Player!$H$1="Active", _xlfn.XLOOKUP( tblChecklist[[#This Row],[TargetID]], tblrecommended[ActiveTargetID], tblrecommended[Order], "" ), _xlfn.XLOOKUP( tblChecklist[[#This Row],[TargetID]], tblrecommended[PassiveTargetID], tblrecommended[Order], "" ) ) ) -> 52
A8: building.alchemists_hut@5 | B8: =_xlfn.XLOOKUP(tblChecklist[[#This Row],[TargetID]],tblTargets[TargetID],tblTargets[DisplayName]) -> Alchemist's Hut Lv 5 | C8: =_xlfn.XLOOKUP( tblChecklist[[#This Row],[TargetID]], tblTargetStatus[TargetID], tblTargetStatus[successors], "" ) -> Alchemist's Hut Lv 6 | D8: BUILDING | E8: =_xlfn.XLOOKUP(tblChecklist[[#This Row],[TargetID]],tblTargetStatus[TargetID],tblTargetStatus[ChainAwareStatus],"") -> BLOCKED | F8: 53 | G8: FALSE | H8: =_xlfn.XLOOKUP(tblChecklist[[#This Row],[TargetID]],tblTargetStatus[TargetID],tblTargetStatus[TargetFunded],"") -> FALSE | I8: =IF( tblChecklist[[#This Row],[TargetType]]<>"BUILDING", "", IF( Player!$H$1="Active", _xlfn.XLOOKUP( tblChecklist[[#This Row],[TargetID]], tblrecommended[ActiveTargetID], tblrecommended[Order], "" ), _xlfn.XLOOKUP( tblChecklist[[#This Row],[TargetID]], tblrecommended[PassiveTargetID], tblrecommended[Order], "" ) ) ) -> 53
A9: building.alchemists_hut@6 | B9: =_xlfn.XLOOKUP(tblChecklist[[#This Row],[TargetID]],tblTargets[TargetID],tblTargets[DisplayName]) -> Alchemist's Hut Lv 6 | C9: =_xlfn.XLOOKUP( tblChecklist[[#This Row],[TargetID]], tblTargetStatus[TargetID], tblTargetStatus[successors], "" ) -> Alchemists Hut maxed, Flamethrower, Tetrachloroaurate | D9: BUILDING | E9: =_xlfn.XLOOKUP(tblChecklist[[#This Row],[TargetID]],tblTargetStatus[TargetID],tblTargetStatus[ChainAwareStatus],"") -> BLOCKED | F9: 54 | G9: FALSE | H9: =_xlfn.XLOOKUP(tblChecklist[[#This Row],[TargetID]],tblTargetStatus[TargetID],tblTargetStatus[TargetFunded],"") -> FALSE | I9: =IF( tblChecklist[[#This Row],[TargetType]]<>"BUILDING", "", IF( Player!$H$1="Active", _xlfn.XLOOKUP( tblChecklist[[#This Row],[TargetID]], tblrecommended[ActiveTargetID], tblrecommended[Order], "" ), _xlfn.XLOOKUP( tblChecklist[[#This Row],[TargetID]], tblrecommended[PassiveTargetID], tblrecommended[Order], "" ) ) ) -> 54
A10: building.bonsai@1 | B10: =_xlfn.XLOOKUP(tblChecklist[[#This Row],[TargetID]],tblTargets[TargetID],tblTargets[DisplayName]) -> Bonsai Lv 1 | C10: =_xlfn.XLOOKUP( tblChecklist[[#This Row],[TargetID]], tblTargetStatus[TargetID], tblTargetStatus[successors], "" ) -> Bonsai Lv 2 | D10: BUILDING | E10: =_xlfn.XLOOKUP(tblChecklist[[#This Row],[TargetID]],tblTargetStatus[TargetID],tblTargetStatus[ChainAwareStatus],"") -> ONE AWAY | F10: 89 | G10: FALSE | H10: =_xlfn.XLOOKUP(tblChecklist[[#This Row],[TargetID]],tblTargetStatus[TargetID],tblTargetStatus[TargetFunded],"") -> FALSE | I10: =IF( tblChecklist[[#This Row],[TargetType]]<>"BUILDING", "", IF( Player!$H$1="Active", _xlfn.XLOOKUP( tblChecklist[[#This Row],[TargetID]], tblrecommended[ActiveTargetID], tblrecommended[Order], "" ), _xlfn.XLOOKUP( tblChecklist[[#This Row],[TargetID]], tblrecommended[PassiveTargetID], tblrecommended[Order], "" ) ) ) -> 89
A11: building.bonsai@2 | B11: =_xlfn.XLOOKUP(tblChecklist[[#This Row],[TargetID]],tblTargets[TargetID],tblTargets[DisplayName]) -> Bonsai Lv 2 | C11: =_xlfn.XLOOKUP( tblChecklist[[#This Row],[TargetID]], tblTargetStatus[TargetID], tblTargetStatus[successors], "" ) | D11: BUILDING | E11: =_xlfn.XLOOKUP(tblChecklist[[#This Row],[TargetID]],tblTargetStatus[TargetID],tblTargetStatus[ChainAwareStatus],"") -> BLOCKED | F11: 90 | G11: FALSE | H11: =_xlfn.XLOOKUP(tblChecklist[[#This Row],[TargetID]],tblTargetStatus[TargetID],tblTargetStatus[TargetFunded],"") -> FALSE | I11: =IF( tblChecklist[[#This Row],[TargetType]]<>"BUILDING", "", IF( Player!$H$1="Active", _xlfn.XLOOKUP( tblChecklist[[#This Row],[TargetID]], tblrecommended[ActiveTargetID], tblrecommended[Order], "" ), _xlfn.XLOOKUP( tblChecklist[[#This Row],[TargetID]], tblrecommended[PassiveTargetID], tblrecommended[Order], "" ) ) ) -> 90
A12: building.bridge@1 | B12: =_xlfn.XLOOKUP(tblChecklist[[#This Row],[TargetID]],tblTargets[TargetID],tblTargets[DisplayName]) -> Bridge Lv 1 | C12: =_xlfn.XLOOKUP( tblChecklist[[#This Row],[TargetID]], tblTargetStatus[TargetID], tblTargetStatus[successors], "" ) -> Airship Lv 1, Bridge maxed, Caravan Lv 1, Outpost Lv 1, Station Lv 1, Tailor Lv 1, Guild Banner, Guild Codex, Guild Supplies, Festival Accepted, Honor, Glory, Sushi Accepted, Silk Road Accepted | D12: BUILDING | E12: =_xlfn.XLOOKUP(tblChecklist[[#This Row],[TargetID]],tblTargetStatus[TargetID],tblTargetStatus[ChainAwareStatus],"") -> ONE AWAY | F12: 27 | G12: FALSE | H12: =_xlfn.XLOOKUP(tblChecklist[[#This Row],[TargetID]],tblTargetStatus[TargetID],tblTargetStatus[TargetFunded],"") -> FALSE | I12: =IF( tblChecklist[[#This Row],[TargetType]]<>"BUILDING", "", IF( Player!$H$1="Active", _xlfn.XLOOKUP( tblChecklist[[#This Row],[TargetID]], tblrecommended[ActiveTargetID], tblrecommended[Order], "" ), _xlfn.XLOOKUP( tblChecklist[[#This Row],[TargetID]], tblrecommended[PassiveTargetID], tblrecommended[Order], "" ) ) ) -> 27
A13: building.caravan@1 | B13: =_xlfn.XLOOKUP(tblChecklist[[#This Row],[TargetID]],tblTargets[TargetID],tblTargets[DisplayName]) -> Caravan Lv 1 | C13: =_xlfn.XLOOKUP( tblChecklist[[#This Row],[TargetID]], tblTargetStatus[TargetID], tblTargetStatus[successors], "" ) -> Caravan Lv 2 | D13: BUILDING | E13: =_xlfn.XLOOKUP(tblChecklist[[#This Row],[TargetID]],tblTargetStatus[TargetID],tblTargetStatus[ChainAwareStatus],"") -> BLOCKED | F13: 36 | G13: FALSE | H13: =_xlfn.XLOOKUP(tblChecklist[[#This Row],[TargetID]],tblTargetStatus[TargetID],tblTargetStatus[TargetFunded],"") -> FALSE | I13: =IF( tblChecklist[[#This Row],[TargetType]]<>"BUILDING", "", IF( Player!$H$1="Active", _xlfn.XLOOKUP( tblChecklist[[#This Row],[TargetID]], tblrecommended[ActiveTargetID], tblrecommended[Order], "" ), _xlfn.XLOOKUP( tblChecklist[[#This Row],[TargetID]], tblrecommended[PassiveTargetID], tblrecommended[Order], "" ) ) ) -> 36
... A25: building.dungeon@5 | B25: =_xlfn.XLOOKUP(tblChecklist[[#This Row],[TargetID]],tblTargets[TargetID],tblTargets[DisplayName]) -> Dungeon Lv 5 | C25: =_xlfn.XLOOKUP( tblChecklist[[#This Row],[TargetID]], tblTargetStatus[TargetID], tblTargetStatus[successors], "" ) -> dungeon maxed, Dungeon Lv 6, Attic, Courtyard, Lair lvl. 1, Tavern, Metal Detector, Magic Beans Accepted, Tame A Critter, Complete Dungeon 5C | D25: BUILDING | E25: =_xlfn.XLOOKUP(tblChecklist[[#This Row],[TargetID]],tblTargetStatus[TargetID],tblTargetStatus[ChainAwareStatus],"") -> BLOCKED | F25: 65 | G25: FALSE | H25: =_xlfn.XLOOKUP(tblChecklist[[#This Row],[TargetID]],tblTargetStatus[TargetID],tblTargetStatus[TargetFunded],"") -> FALSE | I25: =IF( tblChecklist[[#This Row],[TargetType]]<>"BUILDING", "", IF( Player!$H$1="Active", _xlfn.XLOOKUP( tblChecklist[[#This Row],[TargetID]], tblrecommended[ActiveTargetID], tblrecommended[Order], "" ), _xlfn.XLOOKUP( tblChecklist[[#This Row],[TargetID]], tblrecommended[PassiveTargetID], tblrecommended[Order], "" ) ) ) -> 65
A26: building.dungeon@6 | B26: =_xlfn.XLOOKUP(tblChecklist[[#This Row],[TargetID]],tblTargets[TargetID],tblTargets[DisplayName]) -> Dungeon Lv 6 | C26: =_xlfn.XLOOKUP( tblChecklist[[#This Row],[TargetID]], tblTargetStatus[TargetID], tblTargetStatus[successors], "" ) -> Complete Dungeon 6C | D26: BUILDING | E26: =_xlfn.XLOOKUP(tblChecklist[[#This Row],[TargetID]],tblTargetStatus[TargetID],tblTargetStatus[ChainAwareStatus],"") -> BLOCKED | G26: FALSE | H26: =_xlfn.XLOOKUP(tblChecklist[[#This Row],[TargetID]],tblTargetStatus[TargetID],tblTargetStatus[TargetFunded],"") -> N/A | I26: =IF( tblChecklist[[#This Row],[TargetType]]<>"BUILDING", "", IF( Player!$H$1="Active", _xlfn.XLOOKUP( tblChecklist[[#This Row],[TargetID]], tblrecommended[ActiveTargetID], tblrecommended[Order], "" ), _xlfn.XLOOKUP( tblChecklist[[#This Row],[TargetID]], tblrecommended[PassiveTargetID], tblrecommended[Order], "" ) ) )
A27: building.fermentory@1 | B27: =_xlfn.XLOOKUP(tblChecklist[[#This Row],[TargetID]],tblTargets[TargetID],tblTargets[DisplayName]) -> Fermentory Lv 1 | C27: =_xlfn.XLOOKUP( tblChecklist[[#This Row],[TargetID]], tblTargetStatus[TargetID], tblTargetStatus[successors], "" ) -> Fermentory Lv 2 | D27: =_xlfn.XLOOKUP(tblChecklist[[#This Row],[TargetID]],tblTargets[TargetID],tblTargets[TargetType],"") -> BUILDING | E27: =_xlfn.XLOOKUP(tblChecklist[[#This Row],[TargetID]],tblTargetStatus[TargetID],tblTargetStatus[ChainAwareStatus],"") -> BLOCKED | F27: 72 | G27: FALSE | H27: =_xlfn.XLOOKUP(tblChecklist[[#This Row],[TargetID]],tblTargetStatus[TargetID],tblTargetStatus[TargetFunded],"") -> FALSE | I27: =IF( tblChecklist[[#This Row],[TargetType]]<>"BUILDING", "", IF( Player!$H$1="Active", _xlfn.XLOOKUP( tblChecklist[[#This Row],[TargetID]], tblrecommended[ActiveTargetID], tblrecommended[Order], "" ), _xlfn.XLOOKUP( tblChecklist[[#This Row],[TargetID]], tblrecommended[PassiveTargetID], tblrecommended[Order], "" ) ) ) -> 72
A28: building.fermentory@2 | B28: =_xlfn.XLOOKUP(tblChecklist[[#This Row],[TargetID]],tblTargets[TargetID],tblTargets[DisplayName]) -> Fermentory Lv 2 | C28: =_xlfn.XLOOKUP( tblChecklist[[#This Row],[TargetID]], tblTargetStatus[TargetID], tblTargetStatus[successors], "" ) -> Fermentory Lv 3 | D28: =_xlfn.XLOOKUP(tblChecklist[[#This Row],[TargetID]],tblTargets[TargetID],tblTargets[TargetType],"") -> BUILDING | E28: =_xlfn.XLOOKUP(tblChecklist[[#This Row],[TargetID]],tblTargetStatus[TargetID],tblTargetStatus[ChainAwareStatus],"") -> BLOCKED | F28: 73 | G28: FALSE | H28: =_xlfn.XLOOKUP(tblChecklist[[#This Row],[TargetID]],tblTargetStatus[TargetID],tblTargetStatus[TargetFunded],"") -> FALSE | I28: =IF( tblChecklist[[#This Row],[TargetType]]<>"BUILDING", "", IF( Player!$H$1="Active", _xlfn.XLOOKUP( tblChecklist[[#This Row],[TargetID]], tblrecommended[ActiveTargetID], tblrecommended[Order], "" ), _xlfn.XLOOKUP( tblChecklist[[#This Row],[TargetID]], tblrecommended[PassiveTargetID], tblrecommended[Order], "" ) ) ) -> 73
A29: building.fermentory@3 | B29: =_xlfn.XLOOKUP(tblChecklist[[#This Row],[TargetID]],tblTargets[TargetID],tblTargets[DisplayName]) -> Fermentory Lv 3 | C29: =_xlfn.XLOOKUP( tblChecklist[[#This Row],[TargetID]], tblTargetStatus[TargetID], tblTargetStatus[successors], "" ) -> Fermentory Lv 4 | D29: =_xlfn.XLOOKUP(tblChecklist[[#This Row],[TargetID]],tblTargets[TargetID],tblTargets[TargetType],"") -> BUILDING | E29: =_xlfn.XLOOKUP(tblChecklist[[#This Row],[TargetID]],tblTargetStatus[TargetID],tblTargetStatus[ChainAwareStatus],"") -> BLOCKED | F29: 74 | G29: FALSE | H29: =_xlfn.XLOOKUP(tblChecklist[[#This Row],[TargetID]],tblTargetStatus[TargetID],tblTargetStatus[TargetFunded],"") -> FALSE | I29: =IF( tblChecklist[[#This Row],[TargetType]]<>"BUILDING", "", IF( Player!$H$1="Active", _xlfn.XLOOKUP( tblChecklist[[#This Row],[TargetID]], tblrecommended[ActiveTargetID], tblrecommended[Order], "" ), _xlfn.XLOOKUP( tblChecklist[[#This Row],[TargetID]], tblrecommended[PassiveTargetID], tblrecommended[Order], "" ) ) ) -> 74
A30: building.fermentory@4 | B30: =_xlfn.XLOOKUP(tblChecklist[[#This Row],[TargetID]],tblTargets[TargetID],tblTargets[DisplayName]) -> Fermentory Lv 4 | C30: =_xlfn.XLOOKUP( tblChecklist[[#This Row],[TargetID]], tblTargetStatus[TargetID], tblTargetStatus[successors], "" ) -> Fermentory Lv 5 | D30: =_xlfn.XLOOKUP(tblChecklist[[#This Row],[TargetID]],tblTargets[TargetID],tblTargets[TargetType],"") -> BUILDING | E30: =_xlfn.XLOOKUP(tblChecklist[[#This Row],[TargetID]],tblTargetStatus[TargetID],tblTargetStatus[ChainAwareStatus],"") -> BLOCKED | F30: 79 | G30: FALSE | H30: =_xlfn.XLOOKUP(tblChecklist[[#This Row],[TargetID]],tblTargetStatus[TargetID],tblTargetStatus[TargetFunded],"") -> FALSE | I30: =IF( tblChecklist[[#This Row],[TargetType]]<>"BUILDING", "", IF( Player!$H$1="Active", _xlfn.XLOOKUP( tblChecklist[[#This Row],[TargetID]], tblrecommended[ActiveTargetID], tblrecommended[Order], "" ), _xlfn.XLOOKUP( tblChecklist[[#This Row],[TargetID]], tblrecommended[PassiveTargetID], tblrecommended[Order], "" ) ) ) -> 79
A31: building.fermentory@5 | B31: =_xlfn.XLOOKUP(tblChecklist[[#This Row],[TargetID]],tblTargets[TargetID],tblTargets[DisplayName]) -> Fermentory Lv 5 | C31: =_xlfn.XLOOKUP( tblChecklist[[#This Row],[TargetID]], tblTargetStatus[TargetID], tblTargetStatus[successors], "" ) -> Fermentory Lv 6 | D31: =_xlfn.XLOOKUP(tblChecklist[[#This Row],[TargetID]],tblTargets[TargetID],tblTargets[TargetType],"") -> BUILDING | E31: =_xlfn.XLOOKUP(tblChecklist[[#This Row],[TargetID]],tblTargetStatus[TargetID],tblTargetStatus[ChainAwareStatus],"") -> BLOCKED | F31: 80 | G31: FALSE | H31: =_xlfn.XLOOKUP(tblChecklist[[#This Row],[TargetID]],tblTargetStatus[TargetID],tblTargetStatus[TargetFunded],"") -> FALSE | I31: =IF( tblChecklist[[#This Row],[TargetType]]<>"BUILDING", "", IF( Player!$H$1="Active", _xlfn.XLOOKUP( tblChecklist[[#This Row],[TargetID]], tblrecommended[ActiveTargetID], tblrecommended[Order], "" ), _xlfn.XLOOKUP( tblChecklist[[#This Row],[TargetID]], tblrecommended[PassiveTargetID], tblrecommended[Order], "" ) ) ) -> 80
A32: building.fermentory@6 | B32: =_xlfn.XLOOKUP(tblChecklist[[#This Row],[TargetID]],tblTargets[TargetID],tblTargets[DisplayName]) -> Fermentory Lv 6 | C32: =_xlfn.XLOOKUP( tblChecklist[[#This Row],[TargetID]], tblTargetStatus[TargetID], tblTargetStatus[successors], "" ) -> Fermentory maxed, Festival of Beans Accepted | D32: =_xlfn.XLOOKUP(tblChecklist[[#This Row],[TargetID]],tblTargets[TargetID],tblTargets[TargetType],"") -> BUILDING | E32: =_xlfn.XLOOKUP(tblChecklist[[#This Row],[TargetID]],tblTargetStatus[TargetID],tblTargetStatus[ChainAwareStatus],"") -> BLOCKED | F32: 81 | G32: FALSE | H32: =_xlfn.XLOOKUP(tblChecklist[[#This Row],[TargetID]],tblTargetStatus[TargetID],tblTargetStatus[TargetFunded],"") -> FALSE | I32: =IF( tblChecklist[[#This Row],[TargetType]]<>"BUILDING", "", IF( Player!$H$1="Active", _xlfn.XLOOKUP( tblChecklist[[#This Row],[TargetID]], tblrecommended[ActiveTargetID], tblrecommended[Order], "" ), _xlfn.XLOOKUP( tblChecklist[[#This Row],[TargetID]], tblrecommended[PassiveTargetID], tblrecommended[Order], "" ) ) ) -> 81
A33: building.field@1 | B33: =_xlfn.XLOOKUP(tblChecklist[[#This Row],[TargetID]],tblTargets[TargetID],tblTargets[DisplayName]) -> Field Lv 1 | C33: =_xlfn.XLOOKUP( tblChecklist[[#This Row],[TargetID]], tblTargetStatus[TargetID], tblTargetStatus[successors], "" ) -> Field Lv 2, Quest for Knowledge Chapter 1 Finished | D33: =_xlfn.XLOOKUP(tblChecklist[[#This Row],[TargetID]],tblTargets[TargetID],tblTargets[TargetType],"") -> BUILDING | E33: =_xlfn.XLOOKUP(tblChecklist[[#This Row],[TargetID]],tblTargetStatus[TargetID],tblTargetStatus[ChainAwareStatus],"") -> ONE AWAY | F33: 6 | G33: FALSE | H33: =_xlfn.XLOOKUP(tblChecklist[[#This Row],[TargetID]],tblTargetStatus[TargetID],tblTargetStatus[TargetFunded],"") -> FALSE | I33: =IF( tblChecklist[[#This Row],[TargetType]]<>"BUILDING", "", IF( Player!$H$1="Active", _xlfn.XLOOKUP( tblChecklist[[#This Row],[TargetID]], tblrecommended[ActiveTargetID], tblrecommended[Order], "" ), _xlfn.XLOOKUP( tblChecklist[[#This Row],[TargetID]], tblrecommended[PassiveTargetID], tblrecommended[Order], "" ) ) ) -> 6
A34: building.field@2 | B34: =_xlfn.XLOOKUP(tblChecklist[[#This Row],[TargetID]],tblTargets[TargetID],tblTargets[DisplayName]) -> Field Lv 2 | C34: =_xlfn.XLOOKUP( tblChecklist[[#This Row],[TargetID]], tblTargetStatus[TargetID], tblTargetStatus[successors], "" ) -> Field maxed | D34: =_xlfn.XLOOKUP(tblChecklist[[#This Row],[TargetID]],tblTargets[TargetID],tblTargets[TargetType],"") -> BUILDING | E34: =_xlfn.XLOOKUP(tblChecklist[[#This Row],[TargetID]],tblTargetStatus[TargetID],tblTargetStatus[ChainAwareStatus],"") -> BLOCKED | F34: 8 | G34: FALSE | H34: =_xlfn.XLOOKUP(tblChecklist[[#This Row],[TargetID]],tblTargetStatus[TargetID],tblTargetStatus[TargetFunded],"") -> FALSE | I34: =IF( tblChecklist[[#This Row],[TargetType]]<>"BUILDING", "", IF( Player!$H$1="Active", _xlfn.XLOOKUP( tblChecklist[[#This Row],[TargetID]], tblrecommended[ActiveTargetID], tblrecommended[Order], "" ), _xlfn.XLOOKUP( tblChecklist[[#This Row],[TargetID]], tblrecommended[PassiveTargetID], tblrecommended[Order], "" ) ) ) -> 8
A35: building.food_stall@1 | B35: =_xlfn.XLOOKUP(tblChecklist[[#This Row],[TargetID]],tblTargets[TargetID],tblTargets[DisplayName]) -> Food Stall Lv 1 | C35: =_xlfn.XLOOKUP( tblChecklist[[#This Row],[TargetID]], tblTargetStatus[TargetID], tblTargetStatus[successors], "" ) -> Food Stall Lv 2, Quest for Knowledge Chapter 1 Finished | D35: =_xlfn.XLOOKUP(tblChecklist[[#This Row],[TargetID]],tblTargets[TargetID],tblTargets[TargetType],"") -> BUILDING | E35: =_xlfn.XLOOKUP(tblChecklist[[#This Row],[TargetID]],tblTargetStatus[TargetID],tblTargetStatus[ChainAwareStatus],"") -> ONE AWAY | F35: 7 | G35: FALSE | H35: =_xlfn.XLOOKUP(tblChecklist[[#This Row],[TargetID]],tblTargetStatus[TargetID],tblTargetStatus[TargetFunded],"") -> FALSE | I35: =IF( tblChecklist[[#This Row],[TargetType]]<>"BUILDING", "", IF( Player!$H$1="Active", _xlfn.XLOOKUP( tblChecklist[[#This Row],[TargetID]], tblrecommended[ActiveTargetID], tblrecommended[Order], "" ), _xlfn.XLOOKUP( tblChecklist[[#This Row],[TargetID]], tblrecommended[PassiveTargetID], tblrecommended[Order], "" ) ) ) -> 7
A36: building.food_stall@2 | B36: =_xlfn.XLOOKUP(tblChecklist[[#This Row],[TargetID]],tblTargets[TargetID],tblTargets[DisplayName]) -> Food Stall Lv 2 | C36: =_xlfn.XLOOKUP( tblChecklist[[#This Row],[TargetID]], tblTargetStatus[TargetID], tblTargetStatus[successors], "" ) -> Food Stall Lv 3, Shogun's Katana Chapter 3 Finished | D36: =_xlfn.XLOOKUP(tblChecklist[[#This Row],[TargetID]],tblTargets[TargetID],tblTargets[TargetType],"") -> BUILDING | E36: =_xlfn.XLOOKUP(tblChecklist[[#This Row],[TargetID]],tblTargetStatus[TargetID],tblTargetStatus[ChainAwareStatus],"") -> BLOCKED | F36: 25 | G36: FALSE | H36: =_xlfn.XLOOKUP(tblChecklist[[#This Row],[TargetID]],tblTargetStatus[TargetID],tblTargetStatus[TargetFunded],"") -> FALSE | I36: =IF( tblChecklist[[#This Row],[TargetType]]<>"BUILDING", "", IF( Player!$H$1="Active", _xlfn.XLOOKUP( tblChecklist[[#This Row],[TargetID]], tblrecommended[ActiveTargetID], tblrecommended[Order], "" ), _xlfn.XLOOKUP( tblChecklist[[#This Row],[TargetID]], tblrecommended[PassiveTargetID], tblrecommended[Order], "" ) ) ) -> 25
A37: building.food_stall@3 | B37: =_xlfn.XLOOKUP(tblChecklist[[#This Row],[TargetID]],tblTargets[TargetID],tblTargets[DisplayName]) -> Food Stall Lv 3 | C37: =_xlfn.XLOOKUP( tblChecklist[[#This Row],[TargetID]], tblTargetStatus[TargetID], tblTargetStatus[successors], "" ) -> Food stall maxed, Guild Supplies, Shogun's Katana Chapter 6 Finished | D37: =_xlfn.XLOOKUP(tblChecklist[[#This Row],[TargetID]],tblTargets[TargetID],tblTargets[TargetType],"") -> BUILDING | E37: =_xlfn.XLOOKUP(tblChecklist[[#This Row],[TargetID]],tblTargetStatus[TargetID],tblTargetStatus[ChainAwareStatus],"") -> BLOCKED | F37: 26 | G37: FALSE | H37: =_xlfn.XLOOKUP(tblChecklist[[#This Row],[TargetID]],tblTargetStatus[TargetID],tblTargetStatus[TargetFunded],"") -> FALSE | I37: =IF( tblChecklist[[#This Row],[TargetType]]<>"BUILDING", "", IF( Player!$H$1="Active", _xlfn.XLOOKUP( tblChecklist[[#This Row],[TargetID]], tblrecommended[ActiveTargetID], tblrecommended[Order], "" ), _xlfn.XLOOKUP( tblChecklist[[#This Row],[TargetID]], tblrecommended[PassiveTargetID], tblrecommended[Order], "" ) ) ) -> 26
A38: building.furnace@1 | B38: =_xlfn.XLOOKUP(tblChecklist[[#This Row],[TargetID]],tblTargets[TargetID],tblTargets[DisplayName]) -> Furnace Lv 1 | C38: =_xlfn.XLOOKUP( tblChecklist[[#This Row],[TargetID]], tblTargetStatus[TargetID], tblTargetStatus[successors], "" ) -> Furnace Lv 2, Shogun's Katana Chapter 1 Finished | D38: =_xlfn.XLOOKUP(tblChecklist[[#This Row],[TargetID]],tblTargets[TargetID],tblTargets[TargetType],"") -> BUILDING | E38: =_xlfn.XLOOKUP(tblChecklist[[#This Row],[TargetID]],tblTargetStatus[TargetID],tblTargetStatus[ChainAwareStatus],"") -> ONE AWAY | F38: 10 | G38: FALSE | H38: =_xlfn.XLOOKUP(tblChecklist[[#This Row],[TargetID]],tblTargetStatus[TargetID],tblTargetStatus[TargetFunded],"") -> FALSE | I38: =IF( tblChecklist[[#This Row],[TargetType]]<>"BUILDING", "", IF( Player!$H$1="Active", _xlfn.XLOOKUP( tblChecklist[[#This Row],[TargetID]], tblrecommended[ActiveTargetID], tblrecommended[Order], "" ), _xlfn.XLOOKUP( tblChecklist[[#This Row],[TargetID]], tblrecommended[PassiveTargetID], tblrecommended[Order], "" ) ) ) -> 10
... A44: building.gong@1 | B44: =_xlfn.XLOOKUP(tblChecklist[[#This Row],[TargetID]],tblTargets[TargetID],tblTargets[DisplayName]) -> Gong Lv 1 | C44: =_xlfn.XLOOKUP( tblChecklist[[#This Row],[TargetID]], tblTargetStatus[TargetID], tblTargetStatus[successors], "" ) | D44: =_xlfn.XLOOKUP(tblChecklist[[#This Row],[TargetID]],tblTargets[TargetID],tblTargets[TargetType],"") -> BUILDING | E44: =_xlfn.XLOOKUP(tblChecklist[[#This Row],[TargetID]],tblTargetStatus[TargetID],tblTargetStatus[ChainAwareStatus],"") -> ONE AWAY | F44: 102 | G44: FALSE | H44: =_xlfn.XLOOKUP(tblChecklist[[#This Row],[TargetID]],tblTargetStatus[TargetID],tblTargetStatus[TargetFunded],"") -> FALSE | I44: =IF( tblChecklist[[#This Row],[TargetType]]<>"BUILDING", "", IF( Player!$H$1="Active", _xlfn.XLOOKUP( tblChecklist[[#This Row],[TargetID]], tblrecommended[ActiveTargetID], tblrecommended[Order], "" ), _xlfn.XLOOKUP( tblChecklist[[#This Row],[TargetID]], tblrecommended[PassiveTargetID], tblrecommended[Order], "" ) ) ) -> 102
A45: building.guild@1 | B45: =_xlfn.XLOOKUP(tblChecklist[[#This Row],[TargetID]],tblTargets[TargetID],tblTargets[DisplayName]) -> Guild Lv 1 | C45: =_xlfn.XLOOKUP( tblChecklist[[#This Row],[TargetID]], tblTargetStatus[TargetID], tblTargetStatus[successors], "" ) -> Guild Lv 2 | D45: =_xlfn.XLOOKUP(tblChecklist[[#This Row],[TargetID]],tblTargets[TargetID],tblTargets[TargetType],"") -> BUILDING | E45: =_xlfn.XLOOKUP(tblChecklist[[#This Row],[TargetID]],tblTargetStatus[TargetID],tblTargetStatus[ChainAwareStatus],"") -> COMPLETED | G45: TRUE | H45: =_xlfn.XLOOKUP(tblChecklist[[#This Row],[TargetID]],tblTargetStatus[TargetID],tblTargetStatus[TargetFunded],"") -> N/A | I45: =IF( tblChecklist[[#This Row],[TargetType]]<>"BUILDING", "", IF( Player!$H$1="Active", _xlfn.XLOOKUP( tblChecklist[[#This Row],[TargetID]], tblrecommended[ActiveTargetID], tblrecommended[Order], "" ), _xlfn.XLOOKUP( tblChecklist[[#This Row],[TargetID]], tblrecommended[PassiveTargetID], tblrecommended[Order], "" ) ) )
A46: building.guild@2 | B46: =_xlfn.XLOOKUP(tblChecklist[[#This Row],[TargetID]],tblTargets[TargetID],tblTargets[DisplayName]) -> Guild Lv 2 | C46: =_xlfn.XLOOKUP( tblChecklist[[#This Row],[TargetID]], tblTargetStatus[TargetID], tblTargetStatus[successors], "" ) -> Alchemist's Hut Lv 2, Food Stall Lv 2, Guild Lv 3, Warehouse Lv 2 | D46: =_xlfn.XLOOKUP(tblChecklist[[#This Row],[TargetID]],tblTargets[TargetID],tblTargets[TargetType],"") -> BUILDING | E46: =_xlfn.XLOOKUP(tblChecklist[[#This Row],[TargetID]],tblTargetStatus[TargetID],tblTargetStatus[ChainAwareStatus],"") -> READY | F46: 1 | G46: FALSE | H46: =_xlfn.XLOOKUP(tblChecklist[[#This Row],[TargetID]],tblTargetStatus[TargetID],tblTargetStatus[TargetFunded],"") -> FALSE | I46: =IF( tblChecklist[[#This Row],[TargetType]]<>"BUILDING", "", IF( Player!$H$1="Active", _xlfn.XLOOKUP( tblChecklist[[#This Row],[TargetID]], tblrecommended[ActiveTargetID], tblrecommended[Order], "" ), _xlfn.XLOOKUP( tblChecklist[[#This Row],[TargetID]], tblrecommended[PassiveTargetID], tblrecommended[Order], "" ) ) ) -> 1
A47: building.guild@3 | B47: =_xlfn.XLOOKUP(tblChecklist[[#This Row],[TargetID]],tblTargets[TargetID],tblTargets[DisplayName]) -> Guild Lv 3 | C47: =_xlfn.XLOOKUP( tblChecklist[[#This Row],[TargetID]], tblTargetStatus[TargetID], tblTargetStatus[successors], "" ) -> Alchemist's Hut Lv 3, Alchemist's Hut Lv 4, Guild Lv 4, Warehouse Lv 3 | D47: =_xlfn.XLOOKUP(tblChecklist[[#This Row],[TargetID]],tblTargets[TargetID],tblTargets[TargetType],"") -> BUILDING | E47: =_xlfn.XLOOKUP(tblChecklist[[#This Row],[TargetID]],tblTargetStatus[TargetID],tblTargetStatus[ChainAwareStatus],"") -> ONE AWAY | F47: 17 | G47: FALSE | H47: =_xlfn.XLOOKUP(tblChecklist[[#This Row],[TargetID]],tblTargetStatus[TargetID],tblTargetStatus[TargetFunded],"") -> FALSE | I47: =IF( tblChecklist[[#This Row],[TargetType]]<>"BUILDING", "", IF( Player!$H$1="Active", _xlfn.XLOOKUP( tblChecklist[[#This Row],[TargetID]], tblrecommended[ActiveTargetID], tblrecommended[Order], "" ), _xlfn.XLOOKUP( tblChecklist[[#This Row],[TargetID]], tblrecommended[PassiveTargetID], tblrecommended[Order], "" ) ) ) -> 17
A48: building.guild@4 | B48: =_xlfn.XLOOKUP(tblChecklist[[#This Row],[TargetID]],tblTargets[TargetID],tblTargets[DisplayName]) -> Guild Lv 4 | C48: =_xlfn.XLOOKUP( tblChecklist[[#This Row],[TargetID]], tblTargetStatus[TargetID], tblTargetStatus[successors], "" ) -> Alchemist's Hut Lv 4, Guild Lv 5, Warehouse Lv 4 | D48: =_xlfn.XLOOKUP(tblChecklist[[#This Row],[TargetID]],tblTargets[TargetID],tblTargets[TargetType],"") -> BUILDING | E48: =_xlfn.XLOOKUP(tblChecklist[[#This Row],[TargetID]],tblTargetStatus[TargetID],tblTargetStatus[ChainAwareStatus],"") -> BLOCKED | F48: 23 | G48: FALSE | H48: =_xlfn.XLOOKUP(tblChecklist[[#This Row],[TargetID]],tblTargetStatus[TargetID],tblTargetStatus[TargetFunded],"") -> FALSE | I48: =IF( tblChecklist[[#This Row],[TargetType]]<>"BUILDING", "", IF( Player!$H$1="Active", _xlfn.XLOOKUP( tblChecklist[[#This Row],[TargetID]], tblrecommended[ActiveTargetID], tblrecommended[Order], "" ), _xlfn.XLOOKUP( tblChecklist[[#This Row],[TargetID]], tblrecommended[PassiveTargetID], tblrecommended[Order], "" ) ) ) -> 23
A49: building.guild@5 | B49: =_xlfn.XLOOKUP(tblChecklist[[#This Row],[TargetID]],tblTargets[TargetID],tblTargets[DisplayName]) -> Guild Lv 5 | C49: =_xlfn.XLOOKUP( tblChecklist[[#This Row],[TargetID]], tblTargetStatus[TargetID], tblTargetStatus[successors], "" ) -> Alchemist's Hut Lv 5, Warehouse Lv 5, Emerald Tablet, Guild Codex, Historical Library, Trigonometry, Build the Guild Finished | D49: =_xlfn.XLOOKUP(tblChecklist[[#This Row],[TargetID]],tblTargets[TargetID],tblTargets[TargetType],"") -> BUILDING | E49: =_xlfn.XLOOKUP(tblChecklist[[#This Row],[TargetID]],tblTargetStatus[TargetID],tblTargetStatus[ChainAwareStatus],"") -> BLOCKED | F49: 29 | G49: FALSE | H49: =_xlfn.XLOOKUP(tblChecklist[[#This Row],[TargetID]],tblTargetStatus[TargetID],tblTargetStatus[TargetFunded],"") -> FALSE | I49: =IF( tblChecklist[[#This Row],[TargetType]]<>"BUILDING", "", IF( Player!$H$1="Active", _xlfn.XLOOKUP( tblChecklist[[#This Row],[TargetID]], tblrecommended[ActiveTargetID], tblrecommended[Order], "" ), _xlfn.XLOOKUP( tblChecklist[[#This Row],[TargetID]], tblrecommended[PassiveTargetID], tblrecommended[Order], "" ) ) ) -> 29
A50: building.guild_video_game_arcade@1 | B50: =_xlfn.XLOOKUP(tblChecklist[[#This Row],[TargetID]],tblTargets[TargetID],tblTargets[DisplayName]) -> Guild: Video Game Arcade Lv 1 | C50: =_xlfn.XLOOKUP( tblChecklist[[#This Row],[TargetID]], tblTargetStatus[TargetID], tblTargetStatus[successors], "" ) | D50: =_xlfn.XLOOKUP(tblChecklist[[#This Row],[TargetID]],tblTargets[TargetID],tblTargets[TargetType],"") -> BUILDING | E50: =_xlfn.XLOOKUP(tblChecklist[[#This Row],[TargetID]],tblTargetStatus[TargetID],tblTargetStatus[ChainAwareStatus],"") -> BLOCKED | G50: FALSE | H50: =_xlfn.XLOOKUP(tblChecklist[[#This Row],[TargetID]],tblTargetStatus[TargetID],tblTargetStatus[TargetFunded],"") -> FALSE | I50: =IF( tblChecklist[[#This Row],[TargetType]]<>"BUILDING", "", IF( Player!$H$1="Active", _xlfn.XLOOKUP( tblChecklist[[#This Row],[TargetID]], tblrecommended[ActiveTargetID], tblrecommended[Order], "" ), _xlfn.XLOOKUP( tblChecklist[[#This Row],[TargetID]], tblrecommended[PassiveTargetID], tblrecommended[Order], "" ) ) )
A51: building.laboratory@1 | B51: =_xlfn.XLOOKUP(tblChecklist[[#This Row],[TargetID]],tblTargets[TargetID],tblTargets[DisplayName]) -> Laboratory Lv 1 | C51: =_xlfn.XLOOKUP( tblChecklist[[#This Row],[TargetID]], tblTargetStatus[TargetID], tblTargetStatus[successors], "" ) -> Laboratory Lv 2 | D51: =_xlfn.XLOOKUP(tblChecklist[[#This Row],[TargetID]],tblTargets[TargetID],tblTargets[TargetType],"") -> BUILDING | E51: =_xlfn.XLOOKUP(tblChecklist[[#This Row],[TargetID]],tblTargetStatus[TargetID],tblTargetStatus[ChainAwareStatus],"") -> BLOCKED | F51: 66 | G51: FALSE | H51: =_xlfn.XLOOKUP(tblChecklist[[#This Row],[TargetID]],tblTargetStatus[TargetID],tblTargetStatus[TargetFunded],"") -> FALSE | I51: =IF( tblChecklist[[#This Row],[TargetType]]<>"BUILDING", "", IF( Player!$H$1="Active", _xlfn.XLOOKUP( tblChecklist[[#This Row],[TargetID]], tblrecommended[ActiveTargetID], tblrecommended[Order], "" ), _xlfn.XLOOKUP( tblChecklist[[#This Row],[TargetID]], tblrecommended[PassiveTargetID], tblrecommended[Order], "" ) ) ) -> 66
A52: building.laboratory@2 | B52: =_xlfn.XLOOKUP(tblChecklist[[#This Row],[TargetID]],tblTargets[TargetID],tblTargets[DisplayName]) -> Laboratory Lv 2 | C52: =_xlfn.XLOOKUP( tblChecklist[[#This Row],[TargetID]], tblTargetStatus[TargetID], tblTargetStatus[successors], "" ) -> Laboratory Lv 3 | D52: =_xlfn.XLOOKUP(tblChecklist[[#This Row],[TargetID]],tblTargets[TargetID],tblTargets[TargetType],"") -> BUILDING | E52: =_xlfn.XLOOKUP(tblChecklist[[#This Row],[TargetID]],tblTargetStatus[TargetID],tblTargetStatus[ChainAwareStatus],"") -> BLOCKED | F52: 67 | G52: FALSE | H52: =_xlfn.XLOOKUP(tblChecklist[[#This Row],[TargetID]],tblTargetStatus[TargetID],tblTargetStatus[TargetFunded],"") -> FALSE | I52: =IF( tblChecklist[[#This Row],[TargetType]]<>"BUILDING", "", IF( Player!$H$1="Active", _xlfn.XLOOKUP( tblChecklist[[#This Row],[TargetID]], tblrecommended[ActiveTargetID], tblrecommended[Order], "" ), _xlfn.XLOOKUP( tblChecklist[[#This Row],[TargetID]], tblrecommended[PassiveTargetID], tblrecommended[Order], "" ) ) ) -> 67
A53: building.laboratory@3 | B53: =_xlfn.XLOOKUP(tblChecklist[[#This Row],[TargetID]],tblTargets[TargetID],tblTargets[DisplayName]) -> Laboratory Lv 3 | C53: =_xlfn.XLOOKUP( tblChecklist[[#This Row],[TargetID]], tblTargetStatus[TargetID], tblTargetStatus[successors], "" ) -> Laboratory Lv 4 | D53: =_xlfn.XLOOKUP(tblChecklist[[#This Row],[TargetID]],tblTargets[TargetID],tblTargets[TargetType],"") -> BUILDING | E53: =_xlfn.XLOOKUP(tblChecklist[[#This Row],[TargetID]],tblTargetStatus[TargetID],tblTargetStatus[ChainAwareStatus],"") -> BLOCKED | F53: 68 | G53: FALSE | H53: =_xlfn.XLOOKUP(tblChecklist[[#This Row],[TargetID]],tblTargetStatus[TargetID],tblTargetStatus[TargetFunded],"") -> FALSE | I53: =IF( tblChecklist[[#This Row],[TargetType]]<>"BUILDING", "", IF( Player!$H$1="Active", _xlfn.XLOOKUP( tblChecklist[[#This Row],[TargetID]], tblrecommended[ActiveTargetID], tblrecommended[Order], "" ), _xlfn.XLOOKUP( tblChecklist[[#This Row],[TargetID]], tblrecommended[PassiveTargetID], tblrecommended[Order], "" ) ) ) -> 68
A54: building.laboratory@4 | B54: =_xlfn.XLOOKUP(tblChecklist[[#This Row],[TargetID]],tblTargets[TargetID],tblTargets[DisplayName]) -> Laboratory Lv 4 | C54: =_xlfn.XLOOKUP( tblChecklist[[#This Row],[TargetID]], tblTargetStatus[TargetID], tblTargetStatus[successors], "" ) -> Laboratory Lv 5 | D54: =_xlfn.XLOOKUP(tblChecklist[[#This Row],[TargetID]],tblTargets[TargetID],tblTargets[TargetType],"") -> BUILDING | E54: =_xlfn.XLOOKUP(tblChecklist[[#This Row],[TargetID]],tblTargetStatus[TargetID],tblTargetStatus[ChainAwareStatus],"") -> BLOCKED | F54: 75 | G54: FALSE | H54: =_xlfn.XLOOKUP(tblChecklist[[#This Row],[TargetID]],tblTargetStatus[TargetID],tblTargetStatus[TargetFunded],"") -> FALSE | I54: =IF( tblChecklist[[#This Row],[TargetType]]<>"BUILDING", "", IF( Player!$H$1="Active", _xlfn.XLOOKUP( tblChecklist[[#This Row],[TargetID]], tblrecommended[ActiveTargetID], tblrecommended[Order], "" ), _xlfn.XLOOKUP( tblChecklist[[#This Row],[TargetID]], tblrecommended[PassiveTargetID], tblrecommended[Order], "" ) ) ) -> 75
A55: building.laboratory@5 | B55: =_xlfn.XLOOKUP(tblChecklist[[#This Row],[TargetID]],tblTargets[TargetID],tblTargets[DisplayName]) -> Laboratory Lv 5 | C55: =_xlfn.XLOOKUP( tblChecklist[[#This Row],[TargetID]], tblTargetStatus[TargetID], tblTargetStatus[successors], "" ) -> Laboratory maxed, Ahead of Time Chapter 1 Finished | D55: =_xlfn.XLOOKUP(tblChecklist[[#This Row],[TargetID]],tblTargets[TargetID],tblTargets[TargetType],"") -> BUILDING | E55: =_xlfn.XLOOKUP(tblChecklist[[#This Row],[TargetID]],tblTargetStatus[TargetID],tblTargetStatus[ChainAwareStatus],"") -> BLOCKED | F55: 76 | G55: FALSE | H55: =_xlfn.XLOOKUP(tblChecklist[[#This Row],[TargetID]],tblTargetStatus[TargetID],tblTargetStatus[TargetFunded],"") -> FALSE | I55: =IF( tblChecklist[[#This Row],[TargetType]]<>"BUILDING", "", IF( Player!$H$1="Active", _xlfn.XLOOKUP( tblChecklist[[#This Row],[TargetID]], tblrecommended[ActiveTargetID], tblrecommended[Order], "" ), _xlfn.XLOOKUP( tblChecklist[[#This Row],[TargetID]], tblrecommended[PassiveTargetID], tblrecommended[Order], "" ) ) ) -> 76
A56: building.laboratory_data_center@1 | B56: =_xlfn.XLOOKUP(tblChecklist[[#This Row],[TargetID]],tblTargets[TargetID],tblTargets[DisplayName]) -> Laboratory: Data Center Lv 1 | C56: =_xlfn.XLOOKUP( tblChecklist[[#This Row],[TargetID]], tblTargetStatus[TargetID], tblTargetStatus[successors], "" ) -> Laboratory: Data Center maxed, Ahead of Time Chapter 5 Finished | D56: =_xlfn.XLOOKUP(tblChecklist[[#This Row],[TargetID]],tblTargets[TargetID],tblTargets[TargetType],"") -> BUILDING | E56: =_xlfn.XLOOKUP(tblChecklist[[#This Row],[TargetID]],tblTargetStatus[TargetID],tblTargetStatus[ChainAwareStatus],"") -> BLOCKED | G56: FALSE | H56: =_xlfn.XLOOKUP(tblChecklist[[#This Row],[TargetID]],tblTargetStatus[TargetID],tblTargetStatus[TargetFunded],"") -> FALSE | I56: =IF( tblChecklist[[#This Row],[TargetType]]<>"BUILDING", "", IF( Player!$H$1="Active", _xlfn.XLOOKUP( tblChecklist[[#This Row],[TargetID]], tblrecommended[ActiveTargetID], tblrecommended[Order], "" ), _xlfn.XLOOKUP( tblChecklist[[#This Row],[TargetID]], tblrecommended[PassiveTargetID], tblrecommended[Order], "" ) ) )
...

Sheet cost checklist
A1: RequirementID | B1: TargetID | C1: DisplayName | D1: TargetType | E1: ResourceID | F1: PaymentSlot | G1: QuantityRequired | H1: Sort | I1: TargetCompleted | J1: PlayerPaid | R1: {=_xlfn._xlws.SORT( _xlfn.UNIQUE( _xlfn._xlws.FILTER( tblCostChecklist[ResourceID], (tblCostChecklist[PlayerPaid]=FALSE)* (tblCostChecklist[TargetCompleted]="READY") ) ) )} -> coin
A2: cost.building.airship@1.ruby.1 | B2: =_xlfn.TEXTAFTER( _xlfn.TEXTBEFORE(tblCostChecklist[[#This Row],[RequirementID]],".",-2), "cost." ) -> building.airship@1 | C2: =_xlfn.XLOOKUP(tblCostChecklist[[#This Row],[TargetID]],tblTargets[TargetID],tblTargets[DisplayName],"") -> Airship Lv 1 | D2: =_xlfn.XLOOKUP(tblCostChecklist[[#This Row],[TargetID]],tblTargets[TargetID],tblTargets[TargetType],"") -> BUILDING | E2: ruby | F2: 1 | G2: =_xlfn.XLOOKUP( tblCostChecklist[[#This Row],[RequirementID]], tblCost[RequirementID], tblCost[QuantityRequired], "" ) -> 10 | H2: =IF(OR(LEFT(tblCostChecklist[[#This Row],[TargetID]],10)="state.CHAR",RIGHT(tblCostChecklist[[#This Row],[TargetID]],5)="maxed"),0,IF(_xlfn.XLOOKUP(tblCostChecklist[[#This Row],[TargetID]],tblChecklist[TargetID],tblChecklist[PlayerSort])=0,500,_xlfn.XLOOKUP(tblCostChecklist[[#This Row],[TargetID]],tblChecklist[TargetID],tblChecklist[PlayerSort]))) -> 44 | I2: =_xlfn.XLOOKUP(tblCostChecklist[[#This Row],[TargetID]],tblTargetStatus[TargetID],tblTargetStatus[Status]) -> BLOCKED | J2: FALSE | R2: ruby
A3: cost.building.airship@1.coin.1 | B3: =_xlfn.TEXTAFTER( _xlfn.TEXTBEFORE(tblCostChecklist[[#This Row],[RequirementID]],".",-2), "cost." ) -> building.airship@1 | C3: =_xlfn.XLOOKUP(tblCostChecklist[[#This Row],[TargetID]],tblTargets[TargetID],tblTargets[DisplayName],"") -> Airship Lv 1 | D3: =_xlfn.XLOOKUP(tblCostChecklist[[#This Row],[TargetID]],tblTargets[TargetID],tblTargets[TargetType],"") -> BUILDING | E3: coin | F3: 1 | G3: =_xlfn.XLOOKUP( tblCostChecklist[[#This Row],[RequirementID]], tblCost[RequirementID], tblCost[QuantityRequired], "" ) -> 2000 | H3: =IF(OR(LEFT(tblCostChecklist[[#This Row],[TargetID]],10)="state.CHAR",RIGHT(tblCostChecklist[[#This Row],[TargetID]],5)="maxed"),0,IF(_xlfn.XLOOKUP(tblCostChecklist[[#This Row],[TargetID]],tblChecklist[TargetID],tblChecklist[PlayerSort])=0,500,_xlfn.XLOOKUP(tblCostChecklist[[#This Row],[TargetID]],tblChecklist[TargetID],tblChecklist[PlayerSort]))) -> 44 | I3: =_xlfn.XLOOKUP(tblCostChecklist[[#This Row],[TargetID]],tblTargetStatus[TargetID],tblTargetStatus[Status]) -> BLOCKED | J3: FALSE | R3: stone
A4: cost.building.airship@1.silk.1 | B4: =_xlfn.TEXTAFTER( _xlfn.TEXTBEFORE(tblCostChecklist[[#This Row],[RequirementID]],".",-2), "cost." ) -> building.airship@1 | C4: =_xlfn.XLOOKUP(tblCostChecklist[[#This Row],[TargetID]],tblTargets[TargetID],tblTargets[DisplayName],"") -> Airship Lv 1 | D4: =_xlfn.XLOOKUP(tblCostChecklist[[#This Row],[TargetID]],tblTargets[TargetID],tblTargets[TargetType],"") -> BUILDING | E4: silk | F4: 1 | G4: =_xlfn.XLOOKUP( tblCostChecklist[[#This Row],[RequirementID]], tblCost[RequirementID], tblCost[QuantityRequired], "" ) -> 120 | H4: =IF(OR(LEFT(tblCostChecklist[[#This Row],[TargetID]],10)="state.CHAR",RIGHT(tblCostChecklist[[#This Row],[TargetID]],5)="maxed"),0,IF(_xlfn.XLOOKUP(tblCostChecklist[[#This Row],[TargetID]],tblChecklist[TargetID],tblChecklist[PlayerSort])=0,500,_xlfn.XLOOKUP(tblCostChecklist[[#This Row],[TargetID]],tblChecklist[TargetID],tblChecklist[PlayerSort]))) -> 44 | I4: =_xlfn.XLOOKUP(tblCostChecklist[[#This Row],[TargetID]],tblTargetStatus[TargetID],tblTargetStatus[Status]) -> BLOCKED | J4: FALSE | R4: wood
A5: cost.building.airship@1.thread.1 | B5: =_xlfn.TEXTAFTER( _xlfn.TEXTBEFORE(tblCostChecklist[[#This Row],[RequirementID]],".",-2), "cost." ) -> building.airship@1 | C5: =_xlfn.XLOOKUP(tblCostChecklist[[#This Row],[TargetID]],tblTargets[TargetID],tblTargets[DisplayName],"") -> Airship Lv 1 | D5: =_xlfn.XLOOKUP(tblCostChecklist[[#This Row],[TargetID]],tblTargets[TargetID],tblTargets[TargetType],"") -> BUILDING | E5: thread | F5: 1 | G5: =_xlfn.XLOOKUP( tblCostChecklist[[#This Row],[RequirementID]], tblCost[RequirementID], tblCost[QuantityRequired], "" ) -> 20 | H5: =IF(OR(LEFT(tblCostChecklist[[#This Row],[TargetID]],10)="state.CHAR",RIGHT(tblCostChecklist[[#This Row],[TargetID]],5)="maxed"),0,IF(_xlfn.XLOOKUP(tblCostChecklist[[#This Row],[TargetID]],tblChecklist[TargetID],tblChecklist[PlayerSort])=0,500,_xlfn.XLOOKUP(tblCostChecklist[[#This Row],[TargetID]],tblChecklist[TargetID],tblChecklist[PlayerSort]))) -> 44 | I5: =_xlfn.XLOOKUP(tblCostChecklist[[#This Row],[TargetID]],tblTargetStatus[TargetID],tblTargetStatus[Status]) -> BLOCKED | J5: FALSE
A6: cost.building.airship@1.chemicals.1 | B6: =_xlfn.TEXTAFTER( _xlfn.TEXTBEFORE(tblCostChecklist[[#This Row],[RequirementID]],".",-2), "cost." ) -> building.airship@1 | C6: =_xlfn.XLOOKUP(tblCostChecklist[[#This Row],[TargetID]],tblTargets[TargetID],tblTargets[DisplayName],"") -> Airship Lv 1 | D6: =_xlfn.XLOOKUP(tblCostChecklist[[#This Row],[TargetID]],tblTargets[TargetID],tblTargets[TargetType],"") -> BUILDING | E6: chemicals | F6: 1 | G6: =_xlfn.XLOOKUP( tblCostChecklist[[#This Row],[RequirementID]], tblCost[RequirementID], tblCost[QuantityRequired], "" ) -> 200 | H6: =IF(OR(LEFT(tblCostChecklist[[#This Row],[TargetID]],10)="state.CHAR",RIGHT(tblCostChecklist[[#This Row],[TargetID]],5)="maxed"),0,IF(_xlfn.XLOOKUP(tblCostChecklist[[#This Row],[TargetID]],tblChecklist[TargetID],tblChecklist[PlayerSort])=0,500,_xlfn.XLOOKUP(tblCostChecklist[[#This Row],[TargetID]],tblChecklist[TargetID],tblChecklist[PlayerSort]))) -> 44 | I6: =_xlfn.XLOOKUP(tblCostChecklist[[#This Row],[TargetID]],tblTargetStatus[TargetID],tblTargetStatus[Status]) -> BLOCKED | J6: FALSE
A7: cost.building.airship@1.reagent.1 | B7: =_xlfn.TEXTAFTER( _xlfn.TEXTBEFORE(tblCostChecklist[[#This Row],[RequirementID]],".",-2), "cost." ) -> building.airship@1 | C7: =_xlfn.XLOOKUP(tblCostChecklist[[#This Row],[TargetID]],tblTargets[TargetID],tblTargets[DisplayName],"") -> Airship Lv 1 | D7: =_xlfn.XLOOKUP(tblCostChecklist[[#This Row],[TargetID]],tblTargets[TargetID],tblTargets[TargetType],"") -> BUILDING | E7: reagent | F7: 1 | G7: =_xlfn.XLOOKUP( tblCostChecklist[[#This Row],[RequirementID]], tblCost[RequirementID], tblCost[QuantityRequired], "" ) -> 20 | H7: =IF(OR(LEFT(tblCostChecklist[[#This Row],[TargetID]],10)="state.CHAR",RIGHT(tblCostChecklist[[#This Row],[TargetID]],5)="maxed"),0,IF(_xlfn.XLOOKUP(tblCostChecklist[[#This Row],[TargetID]],tblChecklist[TargetID],tblChecklist[PlayerSort])=0,500,_xlfn.XLOOKUP(tblCostChecklist[[#This Row],[TargetID]],tblChecklist[TargetID],tblChecklist[PlayerSort]))) -> 44 | I7: =_xlfn.XLOOKUP(tblCostChecklist[[#This Row],[TargetID]],tblTargetStatus[TargetID],tblTargetStatus[Status]) -> BLOCKED | J7: FALSE
A8: cost.building.airship@1.miron.1 | B8: =_xlfn.TEXTAFTER( _xlfn.TEXTBEFORE(tblCostChecklist[[#This Row],[RequirementID]],".",-2), "cost." ) -> building.airship@1 | C8: =_xlfn.XLOOKUP(tblCostChecklist[[#This Row],[TargetID]],tblTargets[TargetID],tblTargets[DisplayName],"") -> Airship Lv 1 | D8: =_xlfn.XLOOKUP(tblCostChecklist[[#This Row],[TargetID]],tblTargets[TargetID],tblTargets[TargetType],"") -> BUILDING | E8: miron | F8: 1 | G8: =_xlfn.XLOOKUP( tblCostChecklist[[#This Row],[RequirementID]], tblCost[RequirementID], tblCost[QuantityRequired], "" ) -> 50 | H8: =IF(OR(LEFT(tblCostChecklist[[#This Row],[TargetID]],10)="state.CHAR",RIGHT(tblCostChecklist[[#This Row],[TargetID]],5)="maxed"),0,IF(_xlfn.XLOOKUP(tblCostChecklist[[#This Row],[TargetID]],tblChecklist[TargetID],tblChecklist[PlayerSort])=0,500,_xlfn.XLOOKUP(tblCostChecklist[[#This Row],[TargetID]],tblChecklist[TargetID],tblChecklist[PlayerSort]))) -> 44 | I8: =_xlfn.XLOOKUP(tblCostChecklist[[#This Row],[TargetID]],tblTargetStatus[TargetID],tblTargetStatus[Status]) -> BLOCKED | J8: FALSE
A9: cost.building.airship@1.page.1 | B9: =_xlfn.TEXTAFTER( _xlfn.TEXTBEFORE(tblCostChecklist[[#This Row],[RequirementID]],".",-2), "cost." ) -> building.airship@1 | C9: =_xlfn.XLOOKUP(tblCostChecklist[[#This Row],[TargetID]],tblTargets[TargetID],tblTargets[DisplayName],"") -> Airship Lv 1 | D9: =_xlfn.XLOOKUP(tblCostChecklist[[#This Row],[TargetID]],tblTargets[TargetID],tblTargets[TargetType],"") -> BUILDING | E9: page | F9: 1 | G9: =_xlfn.XLOOKUP( tblCostChecklist[[#This Row],[RequirementID]], tblCost[RequirementID], tblCost[QuantityRequired], "" ) -> 40 | H9: =IF(OR(LEFT(tblCostChecklist[[#This Row],[TargetID]],10)="state.CHAR",RIGHT(tblCostChecklist[[#This Row],[TargetID]],5)="maxed"),0,IF(_xlfn.XLOOKUP(tblCostChecklist[[#This Row],[TargetID]],tblChecklist[TargetID],tblChecklist[PlayerSort])=0,500,_xlfn.XLOOKUP(tblCostChecklist[[#This Row],[TargetID]],tblChecklist[TargetID],tblChecklist[PlayerSort]))) -> 44 | I9: =_xlfn.XLOOKUP(tblCostChecklist[[#This Row],[TargetID]],tblTargetStatus[TargetID],tblTargetStatus[Status]) -> BLOCKED | J9: FALSE
A10: cost.building.airship@2.ruby.1 | B10: =_xlfn.TEXTAFTER( _xlfn.TEXTBEFORE(tblCostChecklist[[#This Row],[RequirementID]],".",-2), "cost." ) -> building.airship@2 | C10: =_xlfn.XLOOKUP(tblCostChecklist[[#This Row],[TargetID]],tblTargets[TargetID],tblTargets[DisplayName],"") -> Airship Lv 2 | D10: =_xlfn.XLOOKUP(tblCostChecklist[[#This Row],[TargetID]],tblTargets[TargetID],tblTargets[TargetType],"") -> BUILDING | E10: ruby | F10: 1 | G10: =_xlfn.XLOOKUP( tblCostChecklist[[#This Row],[RequirementID]], tblCost[RequirementID], tblCost[QuantityRequired], "" ) -> 12 | H10: =IF(OR(LEFT(tblCostChecklist[[#This Row],[TargetID]],10)="state.CHAR",RIGHT(tblCostChecklist[[#This Row],[TargetID]],5)="maxed"),0,IF(_xlfn.XLOOKUP(tblCostChecklist[[#This Row],[TargetID]],tblChecklist[TargetID],tblChecklist[PlayerSort])=0,500,_xlfn.XLOOKUP(tblCostChecklist[[#This Row],[TargetID]],tblChecklist[TargetID],tblChecklist[PlayerSort]))) -> 45 | I10: =_xlfn.XLOOKUP(tblCostChecklist[[#This Row],[TargetID]],tblTargetStatus[TargetID],tblTargetStatus[Status]) -> BLOCKED | J10: FALSE
A11: cost.building.airship@2.coin.1 | B11: =_xlfn.TEXTAFTER( _xlfn.TEXTBEFORE(tblCostChecklist[[#This Row],[RequirementID]],".",-2), "cost." ) -> building.airship@2 | C11: =_xlfn.XLOOKUP(tblCostChecklist[[#This Row],[TargetID]],tblTargets[TargetID],tblTargets[DisplayName],"") -> Airship Lv 2 | D11: =_xlfn.XLOOKUP(tblCostChecklist[[#This Row],[TargetID]],tblTargets[TargetID],tblTargets[TargetType],"") -> BUILDING | E11: coin | F11: 1 | G11: =_xlfn.XLOOKUP( tblCostChecklist[[#This Row],[RequirementID]], tblCost[RequirementID], tblCost[QuantityRequired], "" ) -> 3000 | H11: =IF(OR(LEFT(tblCostChecklist[[#This Row],[TargetID]],10)="state.CHAR",RIGHT(tblCostChecklist[[#This Row],[TargetID]],5)="maxed"),0,IF(_xlfn.XLOOKUP(tblCostChecklist[[#This Row],[TargetID]],tblChecklist[TargetID],tblChecklist[PlayerSort])=0,500,_xlfn.XLOOKUP(tblCostChecklist[[#This Row],[TargetID]],tblChecklist[TargetID],tblChecklist[PlayerSort]))) -> 45 | I11: =_xlfn.XLOOKUP(tblCostChecklist[[#This Row],[TargetID]],tblTargetStatus[TargetID],tblTargetStatus[Status]) -> BLOCKED | J11: FALSE
A12: cost.building.airship@2.plank.1 | B12: =_xlfn.TEXTAFTER( _xlfn.TEXTBEFORE(tblCostChecklist[[#This Row],[RequirementID]],".",-2), "cost." ) -> building.airship@2 | C12: =_xlfn.XLOOKUP(tblCostChecklist[[#This Row],[TargetID]],tblTargets[TargetID],tblTargets[DisplayName],"") -> Airship Lv 2 | D12: =_xlfn.XLOOKUP(tblCostChecklist[[#This Row],[TargetID]],tblTargets[TargetID],tblTargets[TargetType],"") -> BUILDING | E12: plank | F12: 1 | G12: =_xlfn.XLOOKUP( tblCostChecklist[[#This Row],[RequirementID]], tblCost[RequirementID], tblCost[QuantityRequired], "" ) -> 60 | H12: =IF(OR(LEFT(tblCostChecklist[[#This Row],[TargetID]],10)="state.CHAR",RIGHT(tblCostChecklist[[#This Row],[TargetID]],5)="maxed"),0,IF(_xlfn.XLOOKUP(tblCostChecklist[[#This Row],[TargetID]],tblChecklist[TargetID],tblChecklist[PlayerSort])=0,500,_xlfn.XLOOKUP(tblCostChecklist[[#This Row],[TargetID]],tblChecklist[TargetID],tblChecklist[PlayerSort]))) -> 45 | I12: =_xlfn.XLOOKUP(tblCostChecklist[[#This Row],[TargetID]],tblTargetStatus[TargetID],tblTargetStatus[Status]) -> BLOCKED | J12: FALSE
A13: cost.building.airship@2.silk.1 | B13: =_xlfn.TEXTAFTER( _xlfn.TEXTBEFORE(tblCostChecklist[[#This Row],[RequirementID]],".",-2), "cost." ) -> building.airship@2 | C13: =_xlfn.XLOOKUP(tblCostChecklist[[#This Row],[TargetID]],tblTargets[TargetID],tblTargets[DisplayName],"") -> Airship Lv 2 | D13: =_xlfn.XLOOKUP(tblCostChecklist[[#This Row],[TargetID]],tblTargets[TargetID],tblTargets[TargetType],"") -> BUILDING | E13: silk | F13: 1 | G13: =_xlfn.XLOOKUP( tblCostChecklist[[#This Row],[RequirementID]], tblCost[RequirementID], tblCost[QuantityRequired], "" ) -> 100 | H13: =IF(OR(LEFT(tblCostChecklist[[#This Row],[TargetID]],10)="state.CHAR",RIGHT(tblCostChecklist[[#This Row],[TargetID]],5)="maxed"),0,IF(_xlfn.XLOOKUP(tblCostChecklist[[#This Row],[TargetID]],tblChecklist[TargetID],tblChecklist[PlayerSort])=0,500,_xlfn.XLOOKUP(tblCostChecklist[[#This Row],[TargetID]],tblChecklist[TargetID],tblChecklist[PlayerSort]))) -> 45 | I13: =_xlfn.XLOOKUP(tblCostChecklist[[#This Row],[TargetID]],tblTargetStatus[TargetID],tblTargetStatus[Status]) -> BLOCKED | J13: FALSE
A14: cost.building.airship@2.gears.1 | B14: =_xlfn.TEXTAFTER( _xlfn.TEXTBEFORE(tblCostChecklist[[#This Row],[RequirementID]],".",-2), "cost." ) -> building.airship@2 | C14: =_xlfn.XLOOKUP(tblCostChecklist[[#This Row],[TargetID]],tblTargets[TargetID],tblTargets[DisplayName],"") -> Airship Lv 2 | D14: =_xlfn.XLOOKUP(tblCostChecklist[[#This Row],[TargetID]],tblTargets[TargetID],tblTargets[TargetType],"") -> BUILDING | E14: gears | F14: 1 | G14: =_xlfn.XLOOKUP( tblCostChecklist[[#This Row],[RequirementID]], tblCost[RequirementID], tblCost[QuantityRequired], "" ) -> 20 | H14: =IF(OR(LEFT(tblCostChecklist[[#This Row],[TargetID]],10)="state.CHAR",RIGHT(tblCostChecklist[[#This Row],[TargetID]],5)="maxed"),0,IF(_xlfn.XLOOKUP(tblCostChecklist[[#This Row],[TargetID]],tblChecklist[TargetID],tblChecklist[PlayerSort])=0,500,_xlfn.XLOOKUP(tblCostChecklist[[#This Row],[TargetID]],tblChecklist[TargetID],tblChecklist[PlayerSort]))) -> 45 | I14: =_xlfn.XLOOKUP(tblCostChecklist[[#This Row],[TargetID]],tblTargetStatus[TargetID],tblTargetStatus[Status]) -> BLOCKED | J14: FALSE
