Workbook
Name Slicer_PlayerCompleted: #REF!
Name Slicer_TargetType: #REF!
Name craftifactNames: #REF!
Name Slicer_ChainAwareStatus: #REF!
Name Slicer_TargetType1: #REF!
Name AllDependencies: Dependencies!$D$1:$E$1000
Name Slicer_PlayerPaid: #REF!
Name Slicer_TargetCompleted: #REF!
Name Slicer_TargetFunded: #REF!
Name NormalizePrereqs: LAMBDA(_xlpm.txt, LET(_xlpm.t,_xlpm.txt,TRIM(SUBSTITUTE(SUBSTITUTE(SUBSTITUTE(SUBSTITUTE(SUBSTITUTE(_xlpm.t,CHAR(10),"|"),"<br/>","|"),"<br>","|"),"/","|"),"\","|"))))
Name SlicerCache_Table_1_Col_4: #N/A
Name SlicerCache_Table_1_Col_5: #N/A
Name SlicerCache_Table_1_Col_7: #N/A
Name SlicerCache_Table_1_Col_8: #N/A
Name SlicerCache_Table_3_Col_4: #N/A
Name SlicerCache_Table_3_Col_9: #N/A
Name SlicerCache_Table_3_Col_10: #N/A

Sheet README

Sheet Player
A1: Setting | B1: Value | C1: PlayerStateID | D1: Description | E1: Note | G1: Player Type | H1: Active | K1: Active
A2: Character Level | B2: 1 | C2: state.character_level | D2: Current player level | E2: Only needs to be tracked until level 80 | K2: Passive
A3: Cartographer | B3: 0 | C3: state.character_cartographer | D3: Current cartographer level | E3: Only needs to be tracked until level 4
A4: Cooking | B4: 0 | C4: state.character_cooking | D4: Current Cooking level | E4: Only needs to be tracked until level 13

Sheet Dashboard
A1: Current Cost | I1: One Away | O1: Open Quests | S1: Pending actions | V1: Funded not Complete | Y1: Select Resource | Z1: ruby | AA1: =IFERROR(__xludf.DUMMYFUNCTION("IFERROR( FILTER( { 'cost checklist'!C2:C1000, 'cost checklist'!G2:G1000, 'cost checklist'!D2:D1000 }, ('cost checklist'!E2:E1000=$Z$1)* ('cost checklist'!J2:J1000=FALSE)* ('cost checklist'!I2:I1000=""READY"") ), ""No ready unpaid tar"&"gets require this resource"" )"),"Guild Lv 2") -> Guild Lv 2 | AB1: =IFERROR(__xludf.DUMMYFUNCTION("""COMPUTED_VALUE"""),1.0) -> 1 | AC1: =IFERROR(__xludf.DUMMYFUNCTION("""COMPUTED_VALUE"""),"BUILDING") -> BUILDING
A2: Target | B2: Type | C2: Sort | D2: Funded | E2: Remaining | F2: Cost Details | I2: Target | J2: Type | K2: Missing | L2: Cost Details | O2: Active Quest | P2: Outstanding Objective | S2: Action | T2: Unlocks | V2: =IFERROR(__xludf.DUMMYFUNCTION("IFERROR( FILTER( { TargetStatus!B2:B1000, TargetStatus!E2:E1000 }, (TargetStatus!C2:C1000=""READY"")* (TargetStatus!X2:X1000=TRUE) ), ""No funded targets waiting for completion"" )"),"No funded targets waiting for completion") -> No funded targets waiting for completion
A3: =IFERROR(__xludf.DUMMYFUNCTION("IFERROR( LET( data, FILTER( { TargetStatus!B2:B1000, TargetStatus!E2:E1000, TargetStatus!R2:R1000, TargetStatus!V2:V1000, TargetStatus!W2:W1000, TargetStatus!Y2:Y1000 }, (TargetStatus!C2:C1000=""READY"")* "&" (TargetStatus!D2:D1000=FALSE)* (TargetStatus!U2:U1000=TRUE)* (TargetStatus!X2:X1000=FALSE) ), sorted, SORT( HSTACK( data, IF(CHOOSECOLS(data,3)="""",1,0) ), 7,TRUE, 3,TRUE ), CHOOSECOLS(sorted,1,2,3,4,5,6) "&" ), ""Nothing currently waiting for payment"" )"),"Guild Lv 2") -> Guild Lv 2 | B3: =IFERROR(__xludf.DUMMYFUNCTION("""COMPUTED_VALUE"""),"BUILDING") -> BUILDING | C3: =IFERROR(__xludf.DUMMYFUNCTION("""COMPUTED_VALUE"""),1.0) -> 1 | D3: =IFERROR(__xludf.DUMMYFUNCTION("""COMPUTED_VALUE"""),0.0) -> 0 | E3: =IFERROR(__xludf.DUMMYFUNCTION("""COMPUTED_VALUE"""),4.0) -> 4 | F3: =IFERROR(__xludf.DUMMYFUNCTION("""COMPUTED_VALUE"""),"coin: 50, ruby: 1, stone: 50, wood: 50") -> coin: 50, ruby: 1, stone: 50, wood: 50 | I3: =IFERROR(__xludf.DUMMYFUNCTION("IFERROR( FILTER( { TargetStatus!B2:B1000, TargetStatus!E2:E1000, TargetStatus!N2:N1000, TargetStatus!O2:O1000 }, (TargetStatus!Q2:Q1000=""ONE AWAY"")* (TargetStatus!D2:D1000=FALSE)* (TargetStatus!T2:T1000=""PLAYER"") ), ""Nothing "&"one step away"" )"),"Alchemist's Hut Lv 1") -> Alchemist's Hut Lv 1 | J3: =IFERROR(__xludf.DUMMYFUNCTION("""COMPUTED_VALUE"""),"BUILDING") -> BUILDING | K3: =IFERROR(__xludf.DUMMYFUNCTION("""COMPUTED_VALUE"""),"Character Level@6") -> Character Level@6 | L3: =IFERROR(__xludf.DUMMYFUNCTION("""COMPUTED_VALUE"""),"1 ruby,140 coin,70 wood,70 stone") -> 1 ruby,140 coin,70 wood,70 stone | O3: =IFERROR(__xludf.DUMMYFUNCTION("IFERROR( FILTER( { QuestObjectives!H2:H1000, QuestObjectives!C2:C1000 }, (QuestObjectives!F2:F1000=TRUE)* (QuestObjectives!G2:G1000=TRUE) ), ""No active quests"" )"),"No active quests") -> No active quests | S3: =IFERROR(__xludf.DUMMYFUNCTION("IFERROR( FILTER( { TargetStatus!B2:B1000, TargetStatus!AA2:AA1000 }, (TargetStatus!C2:C1000=""READY"")* (TargetStatus!E2:E1000=""STATE"")* (TargetStatus!D2:D1000=FALSE)* (TargetStatus!AA2:AA1000<>"""") ), ""No pending quest acceptance"&" actions"" )"),"No pending quest acceptance actions") -> No pending quest acceptance actions
I4: =IFERROR(__xludf.DUMMYFUNCTION("""COMPUTED_VALUE"""),"Bonsai Lv 1") -> Bonsai Lv 1 | J4: =IFERROR(__xludf.DUMMYFUNCTION("""COMPUTED_VALUE"""),"BUILDING") -> BUILDING | K4: =IFERROR(__xludf.DUMMYFUNCTION("""COMPUTED_VALUE"""),"Character Level@21") -> Character Level@21 | L4: =IFERROR(__xludf.DUMMYFUNCTION("""COMPUTED_VALUE"""),"3 ruby,500 coin,500 plank,120 beans") -> 3 ruby,500 coin,500 plank,120 beans
I5: =IFERROR(__xludf.DUMMYFUNCTION("""COMPUTED_VALUE"""),"Bridge Lv 1") -> Bridge Lv 1 | J5: =IFERROR(__xludf.DUMMYFUNCTION("""COMPUTED_VALUE"""),"BUILDING") -> BUILDING | K5: =IFERROR(__xludf.DUMMYFUNCTION("""COMPUTED_VALUE"""),"Character Level@30") -> Character Level@30 | L5: =IFERROR(__xludf.DUMMYFUNCTION("""COMPUTED_VALUE"""),"4 ruby,1000 coin,400 beam,1000 plank,400 stone,100 steel") -> 4 ruby,1000 coin,400 beam,1000 plank,400 stone,100 steel
I6: =IFERROR(__xludf.DUMMYFUNCTION("""COMPUTED_VALUE"""),"Chicken Lv 1") -> Chicken Lv 1 | J6: =IFERROR(__xludf.DUMMYFUNCTION("""COMPUTED_VALUE"""),"BUILDING") -> BUILDING | K6: =IFERROR(__xludf.DUMMYFUNCTION("""COMPUTED_VALUE"""),"Character Level@15") -> Character Level@15 | L6: =IFERROR(__xludf.DUMMYFUNCTION("""COMPUTED_VALUE"""),"2 ruby,400 coin,400 beam,200 stone,20 wheat,10 thread,1 egg") -> 2 ruby,400 coin,400 beam,200 stone,20 wheat,10 thread,1 egg
I7: =IFERROR(__xludf.DUMMYFUNCTION("""COMPUTED_VALUE"""),"Dungeon Lv 1") -> Dungeon Lv 1 | J7: =IFERROR(__xludf.DUMMYFUNCTION("""COMPUTED_VALUE"""),"BUILDING") -> BUILDING | K7: =IFERROR(__xludf.DUMMYFUNCTION("""COMPUTED_VALUE"""),"Character Level@10") -> Character Level@10 | L7: =IFERROR(__xludf.DUMMYFUNCTION("""COMPUTED_VALUE"""),"1 ruby,300 coin,200 wood,50 stone,100 steel,30 fan") -> 1 ruby,300 coin,200 wood,50 stone,100 steel,30 fan
I8: =IFERROR(__xludf.DUMMYFUNCTION("""COMPUTED_VALUE"""),"Field Lv 1") -> Field Lv 1 | J8: =IFERROR(__xludf.DUMMYFUNCTION("""COMPUTED_VALUE"""),"BUILDING") -> BUILDING | K8: =IFERROR(__xludf.DUMMYFUNCTION("""COMPUTED_VALUE"""),"Character Level@7") -> Character Level@7 | L8: =IFERROR(__xludf.DUMMYFUNCTION("""COMPUTED_VALUE"""),"1 ruby,200 coin,100 wood,20 chemicals") -> 1 ruby,200 coin,100 wood,20 chemicals
I9: =IFERROR(__xludf.DUMMYFUNCTION("""COMPUTED_VALUE"""),"Food Stall Lv 1") -> Food Stall Lv 1 | J9: =IFERROR(__xludf.DUMMYFUNCTION("""COMPUTED_VALUE"""),"BUILDING") -> BUILDING | K9: =IFERROR(__xludf.DUMMYFUNCTION("""COMPUTED_VALUE"""),"Character Level@8") -> Character Level@8 | L9: =IFERROR(__xludf.DUMMYFUNCTION("""COMPUTED_VALUE"""),"1 ruby,300 coin,150 wood,150 stone,20 rice") -> 1 ruby,300 coin,150 wood,150 stone,20 rice
I10: =IFERROR(__xludf.DUMMYFUNCTION("""COMPUTED_VALUE"""),"Furnace Lv 1") -> Furnace Lv 1 | J10: =IFERROR(__xludf.DUMMYFUNCTION("""COMPUTED_VALUE"""),"BUILDING") -> BUILDING | K10: =IFERROR(__xludf.DUMMYFUNCTION("""COMPUTED_VALUE"""),"Character Level@8") -> Character Level@8 | L10: =IFERROR(__xludf.DUMMYFUNCTION("""COMPUTED_VALUE"""),"1 ruby,200 coin,100 wood,100 stone") -> 1 ruby,200 coin,100 wood,100 stone
I11: =IFERROR(__xludf.DUMMYFUNCTION("""COMPUTED_VALUE"""),"Garden Lv 1") -> Garden Lv 1 | J11: =IFERROR(__xludf.DUMMYFUNCTION("""COMPUTED_VALUE"""),"BUILDING") -> BUILDING | K11: =IFERROR(__xludf.DUMMYFUNCTION("""COMPUTED_VALUE"""),"Character Level@12") -> Character Level@12 | L11: =IFERROR(__xludf.DUMMYFUNCTION("""COMPUTED_VALUE"""),"1 ruby,400 coin,200 wood,100 stone") -> 1 ruby,400 coin,200 wood,100 stone
I12: =IFERROR(__xludf.DUMMYFUNCTION("""COMPUTED_VALUE"""),"Gong Lv 1") -> Gong Lv 1 | J12: =IFERROR(__xludf.DUMMYFUNCTION("""COMPUTED_VALUE"""),"BUILDING") -> BUILDING | K12: =IFERROR(__xludf.DUMMYFUNCTION("""COMPUTED_VALUE"""),"Character Level@10") -> Character Level@10 | L12: =IFERROR(__xludf.DUMMYFUNCTION("""COMPUTED_VALUE"""),"3 ruby,200 coin,100 wood,50 stone,50 steel") -> 3 ruby,200 coin,100 wood,50 stone,50 steel
I13: =IFERROR(__xludf.DUMMYFUNCTION("""COMPUTED_VALUE"""),"Guild Lv 3") -> Guild Lv 3 | J13: =IFERROR(__xludf.DUMMYFUNCTION("""COMPUTED_VALUE"""),"BUILDING") -> BUILDING | K13: =IFERROR(__xludf.DUMMYFUNCTION("""COMPUTED_VALUE"""),"Guild Lv 2") -> Guild Lv 2 | L13: =IFERROR(__xludf.DUMMYFUNCTION("""COMPUTED_VALUE"""),"2 ruby,150 coin,300 beam,150 stone") -> 2 ruby,150 coin,300 beam,150 stone
I14: =IFERROR(__xludf.DUMMYFUNCTION("""COMPUTED_VALUE"""),"Lumber Lv 1") -> Lumber Lv 1 | J14: =IFERROR(__xludf.DUMMYFUNCTION("""COMPUTED_VALUE"""),"BUILDING") -> BUILDING | K14: =IFERROR(__xludf.DUMMYFUNCTION("""COMPUTED_VALUE"""),"Character Level@11") -> Character Level@11 | L14: =IFERROR(__xludf.DUMMYFUNCTION("""COMPUTED_VALUE"""),"1 ruby,300 coin,150 wood,150 stone") -> 1 ruby,300 coin,150 wood,150 stone
I15: =IFERROR(__xludf.DUMMYFUNCTION("""COMPUTED_VALUE"""),"Onsen Lv 1") -> Onsen Lv 1 | J15: =IFERROR(__xludf.DUMMYFUNCTION("""COMPUTED_VALUE"""),"BUILDING") -> BUILDING | K15: =IFERROR(__xludf.DUMMYFUNCTION("""COMPUTED_VALUE"""),"Character Level@20") -> Character Level@20 | L15: =IFERROR(__xludf.DUMMYFUNCTION("""COMPUTED_VALUE"""),"3 ruby,500 coin,500 plank,400 stone") -> 3 ruby,500 coin,500 plank,400 stone
I16: =IFERROR(__xludf.DUMMYFUNCTION("""COMPUTED_VALUE"""),"Pagoda Lv 1") -> Pagoda Lv 1 | J16: =IFERROR(__xludf.DUMMYFUNCTION("""COMPUTED_VALUE"""),"BUILDING") -> BUILDING | K16: =IFERROR(__xludf.DUMMYFUNCTION("""COMPUTED_VALUE"""),"Character Level@4") -> Character Level@4 | L16: =IFERROR(__xludf.DUMMYFUNCTION("""COMPUTED_VALUE"""),"1 ruby,50 coin,50 wood,50 stone,5 petard") -> 1 ruby,50 coin,50 wood,50 stone,5 petard
I17: =IFERROR(__xludf.DUMMYFUNCTION("""COMPUTED_VALUE"""),"Rock Garden Lv 1") -> Rock Garden Lv 1 | J17: =IFERROR(__xludf.DUMMYFUNCTION("""COMPUTED_VALUE"""),"BUILDING") -> BUILDING | K17: =IFERROR(__xludf.DUMMYFUNCTION("""COMPUTED_VALUE"""),"Character Level@13") -> Character Level@13 | L17: =IFERROR(__xludf.DUMMYFUNCTION("""COMPUTED_VALUE"""),"1 ruby,400 coin,100 wood,200 stone") -> 1 ruby,400 coin,100 wood,200 stone
I18: =IFERROR(__xludf.DUMMYFUNCTION("""COMPUTED_VALUE"""),"Shop Lv 1") -> Shop Lv 1 | J18: =IFERROR(__xludf.DUMMYFUNCTION("""COMPUTED_VALUE"""),"BUILDING") -> BUILDING | K18: =IFERROR(__xludf.DUMMYFUNCTION("""COMPUTED_VALUE"""),"Character Level@3") -> Character Level@3 | L18: =IFERROR(__xludf.DUMMYFUNCTION("""COMPUTED_VALUE"""),"1 ruby,100 coin,20 wood,20 stone") -> 1 ruby,100 coin,20 wood,20 stone
I19: =IFERROR(__xludf.DUMMYFUNCTION("""COMPUTED_VALUE"""),"Smithy Lv 1") -> Smithy Lv 1 | J19: =IFERROR(__xludf.DUMMYFUNCTION("""COMPUTED_VALUE"""),"BUILDING") -> BUILDING | K19: =IFERROR(__xludf.DUMMYFUNCTION("""COMPUTED_VALUE"""),"Character Level@9") -> Character Level@9 | L19: =IFERROR(__xludf.DUMMYFUNCTION("""COMPUTED_VALUE"""),"1 ruby,240 coin,120 wood,120 stone,20 steel") -> 1 ruby,240 coin,120 wood,120 stone,20 steel
I20: =IFERROR(__xludf.DUMMYFUNCTION("""COMPUTED_VALUE"""),"Warehouse Lv 1") -> Warehouse Lv 1 | J20: =IFERROR(__xludf.DUMMYFUNCTION("""COMPUTED_VALUE"""),"BUILDING") -> BUILDING | K20: =IFERROR(__xludf.DUMMYFUNCTION("""COMPUTED_VALUE"""),"Character Level@5") -> Character Level@5 | L20: =IFERROR(__xludf.DUMMYFUNCTION("""COMPUTED_VALUE"""),"1 ruby,100 coin,60 wood,60 stone") -> 1 ruby,100 coin,60 wood,60 stone
I21: =IFERROR(__xludf.DUMMYFUNCTION("""COMPUTED_VALUE"""),"Windmill Lv 1") -> Windmill Lv 1 | J21: =IFERROR(__xludf.DUMMYFUNCTION("""COMPUTED_VALUE"""),"BUILDING") -> BUILDING | K21: =IFERROR(__xludf.DUMMYFUNCTION("""COMPUTED_VALUE"""),"Character Level@9") -> Character Level@9 | L21: =IFERROR(__xludf.DUMMYFUNCTION("""COMPUTED_VALUE"""),"1 ruby,300 coin,150 wood,150 stone,40 steel") -> 1 ruby,300 coin,150 wood,150 stone,40 steel
I22: =IFERROR(__xludf.DUMMYFUNCTION("""COMPUTED_VALUE"""),"Workshop Lv 1") -> Workshop Lv 1 | J22: =IFERROR(__xludf.DUMMYFUNCTION("""COMPUTED_VALUE"""),"BUILDING") -> BUILDING | K22: =IFERROR(__xludf.DUMMYFUNCTION("""COMPUTED_VALUE"""),"Character Level@2") -> Character Level@2 | L22: =IFERROR(__xludf.DUMMYFUNCTION("""COMPUTED_VALUE"""),"1 ruby,20 coin,10 wood,10 stone") -> 1 ruby,20 coin,10 wood,10 stone

Sheet Checklist
A1: TargetID | B1: DisplayName | C1: Successors | D1: TargetType | E1: ChainAwareStatus | F1: PlayerSort | G1: PlayerCompleted | H1: TargetFunded | I1: Recommended
A2: building.airship@1 | B2: {=_xlfn.XLOOKUP(Checklist!$A2,tblTargets[TargetID],tblTargets[DisplayName])} -> Airship Lv 1 | C2: {=_xlfn.XLOOKUP( A2, tblTargetStatus[TargetID], tblTargetStatus[successors], "" )} -> Airship Lv 2, Astrolabe, Cinema Projector, Dagger, Helmet, Safe, Telescope, Tetrachloroaurate, Festival Returns Accepted, Quest for Knowledge Chapter 5 Accepted | D2: {=_xlfn.XLOOKUP( A2, tblTargets[TargetID], tblTargets[TargetType], "" )} -> BUILDING | E2: {=_xlfn.XLOOKUP( A2, tblTargetStatus[TargetID], tblTargetStatus[ChainAwareStatus], "" )} -> BLOCKED | F2: 44 | G2: FALSE | H2: {=_xlfn.XLOOKUP( A2, tblTargetStatus[TargetID], tblTargetStatus[TargetFunded], "" )} -> FALSE | I2: {=IF( D2<>"BUILDING", "", IF( Player!$H$1="Active", _xlfn.XLOOKUP( A2, tblrecommended[ActiveTargetID], tblrecommended[Order], "" ), _xlfn.XLOOKUP( A2, tblrecommended[PassiveTargetID], tblrecommended[Order], "" ) ) )} -> 44
A3: building.airship@2 | B3: {=_xlfn.XLOOKUP(Checklist!$A3,tblTargets[TargetID],tblTargets[DisplayName])} -> Airship Lv 2 | C3: {=_xlfn.XLOOKUP( A3, tblTargetStatus[TargetID], tblTargetStatus[successors], "" )} -> Airship maxed | D3: {=_xlfn.XLOOKUP( A3, tblTargets[TargetID], tblTargets[TargetType], "" )} -> BUILDING | E3: {=_xlfn.XLOOKUP( A3, tblTargetStatus[TargetID], tblTargetStatus[ChainAwareStatus], "" )} -> BLOCKED | F3: 45 | G3: FALSE | H3: {=_xlfn.XLOOKUP( A3, tblTargetStatus[TargetID], tblTargetStatus[TargetFunded], "" )} -> FALSE | I3: {=IF( D3<>"BUILDING", "", IF( Player!$H$1="Active", _xlfn.XLOOKUP( A3, tblrecommended[ActiveTargetID], tblrecommended[Order], "" ), _xlfn.XLOOKUP( A3, tblrecommended[PassiveTargetID], tblrecommended[Order], "" ) ) )} -> 45
A4: building.alchemists_hut@1 | B4: {=_xlfn.XLOOKUP(Checklist!$A4,tblTargets[TargetID],tblTargets[DisplayName])} -> Alchemist's Hut Lv 1 | C4: {=_xlfn.XLOOKUP( A4, tblTargetStatus[TargetID], tblTargetStatus[successors], "" )} -> Alchemist's Hut Lv 2 | D4: {=_xlfn.XLOOKUP( A4, tblTargets[TargetID], tblTargets[TargetType], "" )} -> BUILDING | E4: {=_xlfn.XLOOKUP( A4, tblTargetStatus[TargetID], tblTargetStatus[ChainAwareStatus], "" )} -> ONE AWAY | F4: 4 | G4: FALSE | H4: {=_xlfn.XLOOKUP( A4, tblTargetStatus[TargetID], tblTargetStatus[TargetFunded], "" )} -> FALSE | I4: {=IF( D4<>"BUILDING", "", IF( Player!$H$1="Active", _xlfn.XLOOKUP( A4, tblrecommended[ActiveTargetID], tblrecommended[Order], "" ), _xlfn.XLOOKUP( A4, tblrecommended[PassiveTargetID], tblrecommended[Order], "" ) ) )} -> 4
A5: building.alchemists_hut@2 | B5: {=_xlfn.XLOOKUP(Checklist!$A5,tblTargets[TargetID],tblTargets[DisplayName])} -> Alchemist's Hut Lv 2 | C5: {=_xlfn.XLOOKUP( A5, tblTargetStatus[TargetID], tblTargetStatus[successors], "" )} -> Alchemist's Hut Lv 3 | D5: {=_xlfn.XLOOKUP( A5, tblTargets[TargetID], tblTargets[TargetType], "" )} -> BUILDING | E5: {=_xlfn.XLOOKUP( A5, tblTargetStatus[TargetID], tblTargetStatus[ChainAwareStatus], "" )} -> BLOCKED | F5: 5 | G5: FALSE | H5: {=_xlfn.XLOOKUP( A5, tblTargetStatus[TargetID], tblTargetStatus[TargetFunded], "" )} -> FALSE | I5: {=IF( D5<>"BUILDING", "", IF( Player!$H$1="Active", _xlfn.XLOOKUP( A5, tblrecommended[ActiveTargetID], tblrecommended[Order], "" ), _xlfn.XLOOKUP( A5, tblrecommended[PassiveTargetID], tblrecommended[Order], "" ) ) )} -> 5
A6: building.alchemists_hut@3 | B6: {=_xlfn.XLOOKUP(Checklist!$A6,tblTargets[TargetID],tblTargets[DisplayName])} -> Alchemist's Hut Lv 3 | C6: {=_xlfn.XLOOKUP( A6, tblTargetStatus[TargetID], tblTargetStatus[successors], "" )} -> Alchemist's Hut Lv 4 | D6: {=_xlfn.XLOOKUP( A6, tblTargets[TargetID], tblTargets[TargetType], "" )} -> BUILDING | E6: {=_xlfn.XLOOKUP( A6, tblTargetStatus[TargetID], tblTargetStatus[ChainAwareStatus], "" )} -> BLOCKED | F6: 51 | G6: FALSE | H6: {=_xlfn.XLOOKUP( A6, tblTargetStatus[TargetID], tblTargetStatus[TargetFunded], "" )} -> FALSE | I6: {=IF( D6<>"BUILDING", "", IF( Player!$H$1="Active", _xlfn.XLOOKUP( A6, tblrecommended[ActiveTargetID], tblrecommended[Order], "" ), _xlfn.XLOOKUP( A6, tblrecommended[PassiveTargetID], tblrecommended[Order], "" ) ) )} -> 51
A7: building.alchemists_hut@4 | B7: {=_xlfn.XLOOKUP(Checklist!$A7,tblTargets[TargetID],tblTargets[DisplayName])} -> Alchemist's Hut Lv 4 | C7: {=_xlfn.XLOOKUP( A7, tblTargetStatus[TargetID], tblTargetStatus[successors], "" )} -> Alchemist's Hut Lv 5 | D7: {=_xlfn.XLOOKUP( A7, tblTargets[TargetID], tblTargets[TargetType], "" )} -> BUILDING | E7: {=_xlfn.XLOOKUP( A7, tblTargetStatus[TargetID], tblTargetStatus[ChainAwareStatus], "" )} -> BLOCKED | F7: 52 | G7: FALSE | H7: {=_xlfn.XLOOKUP( A7, tblTargetStatus[TargetID], tblTargetStatus[TargetFunded], "" )} -> FALSE | I7: {=IF( D7<>"BUILDING", "", IF( Player!$H$1="Active", _xlfn.XLOOKUP( A7, tblrecommended[ActiveTargetID], tblrecommended[Order], "" ), _xlfn.XLOOKUP( A7, tblrecommended[PassiveTargetID], tblrecommended[Order], "" ) ) )} -> 52
A8: building.alchemists_hut@5 | B8: {=_xlfn.XLOOKUP(Checklist!$A8,tblTargets[TargetID],tblTargets[DisplayName])} -> Alchemist's Hut Lv 5 | C8: {=_xlfn.XLOOKUP( A8, tblTargetStatus[TargetID], tblTargetStatus[successors], "" )} -> Alchemist's Hut Lv 6 | D8: {=_xlfn.XLOOKUP( A8, tblTargets[TargetID], tblTargets[TargetType], "" )} -> BUILDING | E8: {=_xlfn.XLOOKUP( A8, tblTargetStatus[TargetID], tblTargetStatus[ChainAwareStatus], "" )} -> BLOCKED | F8: 53 | G8: FALSE | H8: {=_xlfn.XLOOKUP( A8, tblTargetStatus[TargetID], tblTargetStatus[TargetFunded], "" )} -> FALSE | I8: {=IF( D8<>"BUILDING", "", IF( Player!$H$1="Active", _xlfn.XLOOKUP( A8, tblrecommended[ActiveTargetID], tblrecommended[Order], "" ), _xlfn.XLOOKUP( A8, tblrecommended[PassiveTargetID], tblrecommended[Order], "" ) ) )} -> 53
A9: building.alchemists_hut@6 | B9: {=_xlfn.XLOOKUP(Checklist!$A9,tblTargets[TargetID],tblTargets[DisplayName])} -> Alchemist's Hut Lv 6 | C9: {=_xlfn.XLOOKUP( A9, tblTargetStatus[TargetID], tblTargetStatus[successors], "" )} -> Alchemists Hut maxed, Flamethrower, Tetrachloroaurate | D9: {=_xlfn.XLOOKUP( A9, tblTargets[TargetID], tblTargets[TargetType], "" )} -> BUILDING | E9: {=_xlfn.XLOOKUP( A9, tblTargetStatus[TargetID], tblTargetStatus[ChainAwareStatus], "" )} -> BLOCKED | F9: 54 | G9: FALSE | H9: {=_xlfn.XLOOKUP( A9, tblTargetStatus[TargetID], tblTargetStatus[TargetFunded], "" )} -> FALSE | I9: {=IF( D9<>"BUILDING", "", IF( Player!$H$1="Active", _xlfn.XLOOKUP( A9, tblrecommended[ActiveTargetID], tblrecommended[Order], "" ), _xlfn.XLOOKUP( A9, tblrecommended[PassiveTargetID], tblrecommended[Order], "" ) ) )} -> 54
A10: building.bonsai@1 | B10: {=_xlfn.XLOOKUP(Checklist!$A10,tblTargets[TargetID],tblTargets[DisplayName])} -> Bonsai Lv 1 | C10: {=_xlfn.XLOOKUP( A10, tblTargetStatus[TargetID], tblTargetStatus[successors], "" )} -> Bonsai Lv 2 | D10: {=_xlfn.XLOOKUP( A10, tblTargets[TargetID], tblTargets[TargetType], "" )} -> BUILDING | E10: {=_xlfn.XLOOKUP( A10, tblTargetStatus[TargetID], tblTargetStatus[ChainAwareStatus], "" )} -> ONE AWAY | F10: 89 | G10: FALSE | H10: {=_xlfn.XLOOKUP( A10, tblTargetStatus[TargetID], tblTargetStatus[TargetFunded], "" )} -> FALSE | I10: {=IF( D10<>"BUILDING", "", IF( Player!$H$1="Active", _xlfn.XLOOKUP( A10, tblrecommended[ActiveTargetID], tblrecommended[Order], "" ), _xlfn.XLOOKUP( A10, tblrecommended[PassiveTargetID], tblrecommended[Order], "" ) ) )} -> 89
A11: building.bonsai@2 | B11: {=_xlfn.XLOOKUP(Checklist!$A11,tblTargets[TargetID],tblTargets[DisplayName])} -> Bonsai Lv 2 | C11: {=_xlfn.XLOOKUP( A11, tblTargetStatus[TargetID], tblTargetStatus[successors], "" )} | D11: {=_xlfn.XLOOKUP( A11, tblTargets[TargetID], tblTargets[TargetType], "" )} -> BUILDING | E11: {=_xlfn.XLOOKUP( A11, tblTargetStatus[TargetID], tblTargetStatus[ChainAwareStatus], "" )} -> BLOCKED | F11: 90 | G11: FALSE | H11: {=_xlfn.XLOOKUP( A11, tblTargetStatus[TargetID], tblTargetStatus[TargetFunded], "" )} -> FALSE | I11: {=IF( D11<>"BUILDING", "", IF( Player!$H$1="Active", _xlfn.XLOOKUP( A11, tblrecommended[ActiveTargetID], tblrecommended[Order], "" ), _xlfn.XLOOKUP( A11, tblrecommended[PassiveTargetID], tblrecommended[Order], "" ) ) )} -> 90
A12: building.bridge@1 | B12: {=_xlfn.XLOOKUP(Checklist!$A12,tblTargets[TargetID],tblTargets[DisplayName])} -> Bridge Lv 1 | C12: {=_xlfn.XLOOKUP( A12, tblTargetStatus[TargetID], tblTargetStatus[successors], "" )} -> Airship Lv 1, Bridge maxed, Caravan Lv 1, Outpost Lv 1, Station Lv 1, Tailor Lv 1, Guild Banner, Guild Codex, Guild Supplies, Festival Accepted, Honor, Glory, Sushi Accepted, Silk Road Accepted | D12: {=_xlfn.XLOOKUP( A12, tblTargets[TargetID], tblTargets[TargetType], "" )} -> BUILDING | E12: {=_xlfn.XLOOKUP( A12, tblTargetStatus[TargetID], tblTargetStatus[ChainAwareStatus], "" )} -> ONE AWAY | F12: 27 | G12: FALSE | H12: {=_xlfn.XLOOKUP( A12, tblTargetStatus[TargetID], tblTargetStatus[TargetFunded], "" )} -> FALSE | I12: {=IF( D12<>"BUILDING", "", IF( Player!$H$1="Active", _xlfn.XLOOKUP( A12, tblrecommended[ActiveTargetID], tblrecommended[Order], "" ), _xlfn.XLOOKUP( A12, tblrecommended[PassiveTargetID], tblrecommended[Order], "" ) ) )} -> 27
A13: building.caravan@1 | B13: {=_xlfn.XLOOKUP(Checklist!$A13,tblTargets[TargetID],tblTargets[DisplayName])} -> Caravan Lv 1 | C13: {=_xlfn.XLOOKUP( A13, tblTargetStatus[TargetID], tblTargetStatus[successors], "" )} -> Caravan Lv 2 | D13: {=_xlfn.XLOOKUP( A13, tblTargets[TargetID], tblTargets[TargetType], "" )} -> BUILDING | E13: {=_xlfn.XLOOKUP( A13, tblTargetStatus[TargetID], tblTargetStatus[ChainAwareStatus], "" )} -> BLOCKED | F13: 36 | G13: FALSE | H13: {=_xlfn.XLOOKUP( A13, tblTargetStatus[TargetID], tblTargetStatus[TargetFunded], "" )} -> FALSE | I13: {=IF( D13<>"BUILDING", "", IF( Player!$H$1="Active", _xlfn.XLOOKUP( A13, tblrecommended[ActiveTargetID], tblrecommended[Order], "" ), _xlfn.XLOOKUP( A13, tblrecommended[PassiveTargetID], tblrecommended[Order], "" ) ) )} -> 36
... A25: building.dungeon@5 | B25: {=_xlfn.XLOOKUP(Checklist!$A25,tblTargets[TargetID],tblTargets[DisplayName])} -> Dungeon Lv 5 | C25: {=_xlfn.XLOOKUP( A25, tblTargetStatus[TargetID], tblTargetStatus[successors], "" )} -> dungeon maxed, Dungeon Lv 6, Attic, Courtyard, Lair lvl. 1, Tavern, Metal Detector, Magic Beans Accepted, Tame A Critter, Complete Dungeon 5C | D25: {=_xlfn.XLOOKUP( A25, tblTargets[TargetID], tblTargets[TargetType], "" )} -> BUILDING | E25: {=_xlfn.XLOOKUP( A25, tblTargetStatus[TargetID], tblTargetStatus[ChainAwareStatus], "" )} -> BLOCKED | F25: 65 | G25: FALSE | H25: {=_xlfn.XLOOKUP( A25, tblTargetStatus[TargetID], tblTargetStatus[TargetFunded], "" )} -> FALSE | I25: {=IF( D25<>"BUILDING", "", IF( Player!$H$1="Active", _xlfn.XLOOKUP( A25, tblrecommended[ActiveTargetID], tblrecommended[Order], "" ), _xlfn.XLOOKUP( A25, tblrecommended[PassiveTargetID], tblrecommended[Order], "" ) ) )} -> 65
A26: building.dungeon@6 | B26: {=_xlfn.XLOOKUP(Checklist!$A26,tblTargets[TargetID],tblTargets[DisplayName])} -> Dungeon Lv 6 | C26: {=_xlfn.XLOOKUP( A26, tblTargetStatus[TargetID], tblTargetStatus[successors], "" )} -> Complete Dungeon 6C | D26: {=_xlfn.XLOOKUP( A26, tblTargets[TargetID], tblTargets[TargetType], "" )} -> BUILDING | E26: {=_xlfn.XLOOKUP( A26, tblTargetStatus[TargetID], tblTargetStatus[ChainAwareStatus], "" )} -> BLOCKED | G26: FALSE | H26: {=_xlfn.XLOOKUP( A26, tblTargetStatus[TargetID], tblTargetStatus[TargetFunded], "" )} -> N/A | I26: {=IF( D26<>"BUILDING", "", IF( Player!$H$1="Active", _xlfn.XLOOKUP( A26, tblrecommended[ActiveTargetID], tblrecommended[Order], "" ), _xlfn.XLOOKUP( A26, tblrecommended[PassiveTargetID], tblrecommended[Order], "" ) ) )}
A27: building.fermentory@1 | B27: {=_xlfn.XLOOKUP(Checklist!$A27,tblTargets[TargetID],tblTargets[DisplayName])} -> Fermentory Lv 1 | C27: {=_xlfn.XLOOKUP( A27, tblTargetStatus[TargetID], tblTargetStatus[successors], "" )} -> Fermentory Lv 2 | D27: {=_xlfn.XLOOKUP( A27, tblTargets[TargetID], tblTargets[TargetType], "" )} -> BUILDING | E27: {=_xlfn.XLOOKUP( A27, tblTargetStatus[TargetID], tblTargetStatus[ChainAwareStatus], "" )} -> BLOCKED | F27: 72 | G27: FALSE | H27: {=_xlfn.XLOOKUP( A27, tblTargetStatus[TargetID], tblTargetStatus[TargetFunded], "" )} -> FALSE | I27: {=IF( D27<>"BUILDING", "", IF( Player!$H$1="Active", _xlfn.XLOOKUP( A27, tblrecommended[ActiveTargetID], tblrecommended[Order], "" ), _xlfn.XLOOKUP( A27, tblrecommended[PassiveTargetID], tblrecommended[Order], "" ) ) )} -> 72
A28: building.fermentory@2 | B28: {=_xlfn.XLOOKUP(Checklist!$A28,tblTargets[TargetID],tblTargets[DisplayName])} -> Fermentory Lv 2 | C28: {=_xlfn.XLOOKUP( A28, tblTargetStatus[TargetID], tblTargetStatus[successors], "" )} -> Fermentory Lv 3 | D28: {=_xlfn.XLOOKUP( A28, tblTargets[TargetID], tblTargets[TargetType], "" )} -> BUILDING | E28: {=_xlfn.XLOOKUP( A28, tblTargetStatus[TargetID], tblTargetStatus[ChainAwareStatus], "" )} -> BLOCKED | F28: 73 | G28: FALSE | H28: {=_xlfn.XLOOKUP( A28, tblTargetStatus[TargetID], tblTargetStatus[TargetFunded], "" )} -> FALSE | I28: {=IF( D28<>"BUILDING", "", IF( Player!$H$1="Active", _xlfn.XLOOKUP( A28, tblrecommended[ActiveTargetID], tblrecommended[Order], "" ), _xlfn.XLOOKUP( A28, tblrecommended[PassiveTargetID], tblrecommended[Order], "" ) ) )} -> 73
A29: building.fermentory@3 | B29: {=_xlfn.XLOOKUP(Checklist!$A29,tblTargets[TargetID],tblTargets[DisplayName])} -> Fermentory Lv 3 | C29: {=_xlfn.XLOOKUP( A29, tblTargetStatus[TargetID], tblTargetStatus[successors], "" )} -> Fermentory Lv 4 | D29: {=_xlfn.XLOOKUP( A29, tblTargets[TargetID], tblTargets[TargetType], "" )} -> BUILDING | E29: {=_xlfn.XLOOKUP( A29, tblTargetStatus[TargetID], tblTargetStatus[ChainAwareStatus], "" )} -> BLOCKED | F29: 74 | G29: FALSE | H29: {=_xlfn.XLOOKUP( A29, tblTargetStatus[TargetID], tblTargetStatus[TargetFunded], "" )} -> FALSE | I29: {=IF( D29<>"BUILDING", "", IF( Player!$H$1="Active", _xlfn.XLOOKUP( A29, tblrecommended[ActiveTargetID], tblrecommended[Order], "" ), _xlfn.XLOOKUP( A29, tblrecommended[PassiveTargetID], tblrecommended[Order], "" ) ) )} -> 74
A30: building.fermentory@4 | B30: {=_xlfn.XLOOKUP(Checklist!$A30,tblTargets[TargetID],tblTargets[DisplayName])} -> Fermentory Lv 4 | C30: {=_xlfn.XLOOKUP( A30, tblTargetStatus[TargetID], tblTargetStatus[successors], "" )} -> Fermentory Lv 5 | D30: {=_xlfn.XLOOKUP( A30, tblTargets[TargetID], tblTargets[TargetType], "" )} -> BUILDING | E30: {=_xlfn.XLOOKUP( A30, tblTargetStatus[TargetID], tblTargetStatus[ChainAwareStatus], "" )} -> BLOCKED | F30: 79 | G30: FALSE | H30: {=_xlfn.XLOOKUP( A30, tblTargetStatus[TargetID], tblTargetStatus[TargetFunded], "" )} -> FALSE | I30: {=IF( D30<>"BUILDING", "", IF( Player!$H$1="Active", _xlfn.XLOOKUP( A30, tblrecommended[ActiveTargetID], tblrecommended[Order], "" ), _xlfn.XLOOKUP( A30, tblrecommended[PassiveTargetID], tblrecommended[Order], "" ) ) )} -> 79
A31: building.fermentory@5 | B31: {=_xlfn.XLOOKUP(Checklist!$A31,tblTargets[TargetID],tblTargets[DisplayName])} -> Fermentory Lv 5 | C31: {=_xlfn.XLOOKUP( A31, tblTargetStatus[TargetID], tblTargetStatus[successors], "" )} -> Fermentory Lv 6 | D31: {=_xlfn.XLOOKUP( A31, tblTargets[TargetID], tblTargets[TargetType], "" )} -> BUILDING | E31: {=_xlfn.XLOOKUP( A31, tblTargetStatus[TargetID], tblTargetStatus[ChainAwareStatus], "" )} -> BLOCKED | F31: 80 | G31: FALSE | H31: {=_xlfn.XLOOKUP( A31, tblTargetStatus[TargetID], tblTargetStatus[TargetFunded], "" )} -> FALSE | I31: {=IF( D31<>"BUILDING", "", IF( Player!$H$1="Active", _xlfn.XLOOKUP( A31, tblrecommended[ActiveTargetID], tblrecommended[Order], "" ), _xlfn.XLOOKUP( A31, tblrecommended[PassiveTargetID], tblrecommended[Order], "" ) ) )} -> 80
A32: building.fermentory@6 | B32: {=_xlfn.XLOOKUP(Checklist!$A32,tblTargets[TargetID],tblTargets[DisplayName])} -> Fermentory Lv 6 | C32: {=_xlfn.XLOOKUP( A32, tblTargetStatus[TargetID], tblTargetStatus[successors], "" )} -> Fermentory maxed, Festival of Beans Accepted | D32: {=_xlfn.XLOOKUP( A32, tblTargets[TargetID], tblTargets[TargetType], "" )} -> BUILDING | E32: {=_xlfn.XLOOKUP( A32, tblTargetStatus[TargetID], tblTargetStatus[ChainAwareStatus], "" )} -> BLOCKED | F32: 81 | G32: FALSE | H32: {=_xlfn.XLOOKUP( A32, tblTargetStatus[TargetID], tblTargetStatus[TargetFunded], "" )} -> FALSE | I32: {=IF( D32<>"BUILDING", "", IF( Player!$H$1="Active", _xlfn.XLOOKUP( A32, tblrecommended[ActiveTargetID], tblrecommended[Order], "" ), _xlfn.XLOOKUP( A32, tblrecommended[PassiveTargetID], tblrecommended[Order], "" ) ) )} -> 81
A33: building.field@1 | B33: {=_xlfn.XLOOKUP(Checklist!$A33,tblTargets[TargetID],tblTargets[DisplayName])} -> Field Lv 1 | C33: {=_xlfn.XLOOKUP( A33, tblTargetStatus[TargetID], tblTargetStatus[successors], "" )} -> Field Lv 2, Quest for Knowledge Chapter 1 Finished | D33: {=_xlfn.XLOOKUP( A33, tblTargets[TargetID], tblTargets[TargetType], "" )} -> BUILDING | E33: {=_xlfn.XLOOKUP( A33, tblTargetStatus[TargetID], tblTargetStatus[ChainAwareStatus], "" )} -> ONE AWAY | F33: 6 | G33: FALSE | H33: {=_xlfn.XLOOKUP( A33, tblTargetStatus[TargetID], tblTargetStatus[TargetFunded], "" )} -> FALSE | I33: {=IF( D33<>"BUILDING", "", IF( Player!$H$1="Active", _xlfn.XLOOKUP( A33, tblrecommended[ActiveTargetID], tblrecommended[Order], "" ), _xlfn.XLOOKUP( A33, tblrecommended[PassiveTargetID], tblrecommended[Order], "" ) ) )} -> 6
A34: building.field@2 | B34: {=_xlfn.XLOOKUP(Checklist!$A34,tblTargets[TargetID],tblTargets[DisplayName])} -> Field Lv 2 | C34: {=_xlfn.XLOOKUP( A34, tblTargetStatus[TargetID], tblTargetStatus[successors], "" )} -> Field maxed | D34: {=_xlfn.XLOOKUP( A34, tblTargets[TargetID], tblTargets[TargetType], "" )} -> BUILDING | E34: {=_xlfn.XLOOKUP( A34, tblTargetStatus[TargetID], tblTargetStatus[ChainAwareStatus], "" )} -> BLOCKED | F34: 8 | G34: FALSE | H34: {=_xlfn.XLOOKUP( A34, tblTargetStatus[TargetID], tblTargetStatus[TargetFunded], "" )} -> FALSE | I34: {=IF( D34<>"BUILDING", "", IF( Player!$H$1="Active", _xlfn.XLOOKUP( A34, tblrecommended[ActiveTargetID], tblrecommended[Order], "" ), _xlfn.XLOOKUP( A34, tblrecommended[PassiveTargetID], tblrecommended[Order], "" ) ) )} -> 8
A35: building.food_stall@1 | B35: {=_xlfn.XLOOKUP(Checklist!$A35,tblTargets[TargetID],tblTargets[DisplayName])} -> Food Stall Lv 1 | C35: {=_xlfn.XLOOKUP( A35, tblTargetStatus[TargetID], tblTargetStatus[successors], "" )} -> Food Stall Lv 2, Quest for Knowledge Chapter 1 Finished | D35: {=_xlfn.XLOOKUP( A35, tblTargets[TargetID], tblTargets[TargetType], "" )} -> BUILDING | E35: {=_xlfn.XLOOKUP( A35, tblTargetStatus[TargetID], tblTargetStatus[ChainAwareStatus], "" )} -> ONE AWAY | F35: 7 | G35: FALSE | H35: {=_xlfn.XLOOKUP( A35, tblTargetStatus[TargetID], tblTargetStatus[TargetFunded], "" )} -> FALSE | I35: {=IF( D35<>"BUILDING", "", IF( Player!$H$1="Active", _xlfn.XLOOKUP( A35, tblrecommended[ActiveTargetID], tblrecommended[Order], "" ), _xlfn.XLOOKUP( A35, tblrecommended[PassiveTargetID], tblrecommended[Order], "" ) ) )} -> 7
A36: building.food_stall@2 | B36: {=_xlfn.XLOOKUP(Checklist!$A36,tblTargets[TargetID],tblTargets[DisplayName])} -> Food Stall Lv 2 | C36: {=_xlfn.XLOOKUP( A36, tblTargetStatus[TargetID], tblTargetStatus[successors], "" )} -> Food Stall Lv 3, Shogun's Katana Chapter 3 Finished | D36: {=_xlfn.XLOOKUP( A36, tblTargets[TargetID], tblTargets[TargetType], "" )} -> BUILDING | E36: {=_xlfn.XLOOKUP( A36, tblTargetStatus[TargetID], tblTargetStatus[ChainAwareStatus], "" )} -> BLOCKED | F36: 25 | G36: FALSE | H36: {=_xlfn.XLOOKUP( A36, tblTargetStatus[TargetID], tblTargetStatus[TargetFunded], "" )} -> FALSE | I36: {=IF( D36<>"BUILDING", "", IF( Player!$H$1="Active", _xlfn.XLOOKUP( A36, tblrecommended[ActiveTargetID], tblrecommended[Order], "" ), _xlfn.XLOOKUP( A36, tblrecommended[PassiveTargetID], tblrecommended[Order], "" ) ) )} -> 25
A37: building.food_stall@3 | B37: {=_xlfn.XLOOKUP(Checklist!$A37,tblTargets[TargetID],tblTargets[DisplayName])} -> Food Stall Lv 3 | C37: {=_xlfn.XLOOKUP( A37, tblTargetStatus[TargetID], tblTargetStatus[successors], "" )} -> Food stall maxed, Guild Supplies, Shogun's Katana Chapter 6 Finished | D37: {=_xlfn.XLOOKUP( A37, tblTargets[TargetID], tblTargets[TargetType], "" )} -> BUILDING | E37: {=_xlfn.XLOOKUP( A37, tblTargetStatus[TargetID], tblTargetStatus[ChainAwareStatus], "" )} -> BLOCKED | F37: 26 | G37: FALSE | H37: {=_xlfn.XLOOKUP( A37, tblTargetStatus[TargetID], tblTargetStatus[TargetFunded], "" )} -> FALSE | I37: {=IF( D37<>"BUILDING", "", IF( Player!$H$1="Active", _xlfn.XLOOKUP( A37, tblrecommended[ActiveTargetID], tblrecommended[Order], "" ), _xlfn.XLOOKUP( A37, tblrecommended[PassiveTargetID], tblrecommended[Order], "" ) ) )} -> 26
A38: building.furnace@1 | B38: {=_xlfn.XLOOKUP(Checklist!$A38,tblTargets[TargetID],tblTargets[DisplayName])} -> Furnace Lv 1 | C38: {=_xlfn.XLOOKUP( A38, tblTargetStatus[TargetID], tblTargetStatus[successors], "" )} -> Furnace Lv 2, Shogun's Katana Chapter 1 Finished | D38: {=_xlfn.XLOOKUP( A38, tblTargets[TargetID], tblTargets[TargetType], "" )} -> BUILDING | E38: {=_xlfn.XLOOKUP( A38, tblTargetStatus[TargetID], tblTargetStatus[ChainAwareStatus], "" )} -> ONE AWAY | F38: 10 | G38: FALSE | H38: {=_xlfn.XLOOKUP( A38, tblTargetStatus[TargetID], tblTargetStatus[TargetFunded], "" )} -> FALSE | I38: {=IF( D38<>"BUILDING", "", IF( Player!$H$1="Active", _xlfn.XLOOKUP( A38, tblrecommended[ActiveTargetID], tblrecommended[Order], "" ), _xlfn.XLOOKUP( A38, tblrecommended[PassiveTargetID], tblrecommended[Order], "" ) ) )} -> 10
... A44: building.gong@1 | B44: {=_xlfn.XLOOKUP(Checklist!$A44,tblTargets[TargetID],tblTargets[DisplayName])} -> Gong Lv 1 | C44: {=_xlfn.XLOOKUP( A44, tblTargetStatus[TargetID], tblTargetStatus[successors], "" )} | D44: {=_xlfn.XLOOKUP( A44, tblTargets[TargetID], tblTargets[TargetType], "" )} -> BUILDING | E44: {=_xlfn.XLOOKUP( A44, tblTargetStatus[TargetID], tblTargetStatus[ChainAwareStatus], "" )} -> ONE AWAY | F44: 102 | G44: FALSE | H44: {=_xlfn.XLOOKUP( A44, tblTargetStatus[TargetID], tblTargetStatus[TargetFunded], "" )} -> FALSE | I44: {=IF( D44<>"BUILDING", "", IF( Player!$H$1="Active", _xlfn.XLOOKUP( A44, tblrecommended[ActiveTargetID], tblrecommended[Order], "" ), _xlfn.XLOOKUP( A44, tblrecommended[PassiveTargetID], tblrecommended[Order], "" ) ) )} -> 102
A45: building.guild@1 | B45: {=_xlfn.XLOOKUP(Checklist!$A45,tblTargets[TargetID],tblTargets[DisplayName])} -> Guild Lv 1 | C45: {=_xlfn.XLOOKUP( A45, tblTargetStatus[TargetID], tblTargetStatus[successors], "" )} -> Guild Lv 2 | D45: {=_xlfn.XLOOKUP( A45, tblTargets[TargetID], tblTargets[TargetType], "" )} -> BUILDING | E45: {=_xlfn.XLOOKUP( A45, tblTargetStatus[TargetID], tblTargetStatus[ChainAwareStatus], "" )} -> COMPLETED | G45: TRUE | H45: {=_xlfn.XLOOKUP( A45, tblTargetStatus[TargetID], tblTargetStatus[TargetFunded], "" )} -> N/A | I45: {=IF( D45<>"BUILDING", "", IF( Player!$H$1="Active", _xlfn.XLOOKUP( A45, tblrecommended[ActiveTargetID], tblrecommended[Order], "" ), _xlfn.XLOOKUP( A45, tblrecommended[PassiveTargetID], tblrecommended[Order], "" ) ) )}
A46: building.guild@2 | B46: {=_xlfn.XLOOKUP(Checklist!$A46,tblTargets[TargetID],tblTargets[DisplayName])} -> Guild Lv 2 | C46: {=_xlfn.XLOOKUP( A46, tblTargetStatus[TargetID], tblTargetStatus[successors], "" )} -> Alchemist's Hut Lv 2, Food Stall Lv 2, Guild Lv 3, Warehouse Lv 2 | D46: {=_xlfn.XLOOKUP( A46, tblTargets[TargetID], tblTargets[TargetType], "" )} -> BUILDING | E46: {=_xlfn.XLOOKUP( A46, tblTargetStatus[TargetID], tblTargetStatus[ChainAwareStatus], "" )} -> READY | F46: 1 | G46: FALSE | H46: {=_xlfn.XLOOKUP( A46, tblTargetStatus[TargetID], tblTargetStatus[TargetFunded], "" )} -> FALSE | I46: {=IF( D46<>"BUILDING", "", IF( Player!$H$1="Active", _xlfn.XLOOKUP( A46, tblrecommended[ActiveTargetID], tblrecommended[Order], "" ), _xlfn.XLOOKUP( A46, tblrecommended[PassiveTargetID], tblrecommended[Order], "" ) ) )} -> 1
A47: building.guild@3 | B47: {=_xlfn.XLOOKUP(Checklist!$A47,tblTargets[TargetID],tblTargets[DisplayName])} -> Guild Lv 3 | C47: {=_xlfn.XLOOKUP( A47, tblTargetStatus[TargetID], tblTargetStatus[successors], "" )} -> Alchemist's Hut Lv 3, Alchemist's Hut Lv 4, Guild Lv 4, Warehouse Lv 3 | D47: {=_xlfn.XLOOKUP( A47, tblTargets[TargetID], tblTargets[TargetType], "" )} -> BUILDING | E47: {=_xlfn.XLOOKUP( A47, tblTargetStatus[TargetID], tblTargetStatus[ChainAwareStatus], "" )} -> ONE AWAY | F47: 17 | G47: FALSE | H47: {=_xlfn.XLOOKUP( A47, tblTargetStatus[TargetID], tblTargetStatus[TargetFunded], "" )} -> FALSE | I47: {=IF( D47<>"BUILDING", "", IF( Player!$H$1="Active", _xlfn.XLOOKUP( A47, tblrecommended[ActiveTargetID], tblrecommended[Order], "" ), _xlfn.XLOOKUP( A47, tblrecommended[PassiveTargetID], tblrecommended[Order], "" ) ) )} -> 17
A48: building.guild@4 | B48: {=_xlfn.XLOOKUP(Checklist!$A48,tblTargets[TargetID],tblTargets[DisplayName])} -> Guild Lv 4 | C48: {=_xlfn.XLOOKUP( A48, tblTargetStatus[TargetID], tblTargetStatus[successors], "" )} -> Alchemist's Hut Lv 4, Guild Lv 5, Warehouse Lv 4 | D48: {=_xlfn.XLOOKUP( A48, tblTargets[TargetID], tblTargets[TargetType], "" )} -> BUILDING | E48: {=_xlfn.XLOOKUP( A48, tblTargetStatus[TargetID], tblTargetStatus[ChainAwareStatus], "" )} -> BLOCKED | F48: 23 | G48: FALSE | H48: {=_xlfn.XLOOKUP( A48, tblTargetStatus[TargetID], tblTargetStatus[TargetFunded], "" )} -> FALSE | I48: {=IF( D48<>"BUILDING", "", IF( Player!$H$1="Active", _xlfn.XLOOKUP( A48, tblrecommended[ActiveTargetID], tblrecommended[Order], "" ), _xlfn.XLOOKUP( A48, tblrecommended[PassiveTargetID], tblrecommended[Order], "" ) ) )} -> 23
A49: building.guild@5 | B49: {=_xlfn.XLOOKUP(Checklist!$A49,tblTargets[TargetID],tblTargets[DisplayName])} -> Guild Lv 5 | C49: {=_xlfn.XLOOKUP( A49, tblTargetStatus[TargetID], tblTargetStatus[successors], "" )} -> Alchemist's Hut Lv 5, Warehouse Lv 5, Emerald Tablet, Guild Codex, Historical Library, Trigonometry, Build the Guild Finished | D49: {=_xlfn.XLOOKUP( A49, tblTargets[TargetID], tblTargets[TargetType], "" )} -> BUILDING | E49: {=_xlfn.XLOOKUP( A49, tblTargetStatus[TargetID], tblTargetStatus[ChainAwareStatus], "" )} -> BLOCKED | F49: 29 | G49: FALSE | H49: {=_xlfn.XLOOKUP( A49, tblTargetStatus[TargetID], tblTargetStatus[TargetFunded], "" )} -> FALSE | I49: {=IF( D49<>"BUILDING", "", IF( Player!$H$1="Active", _xlfn.XLOOKUP( A49, tblrecommended[ActiveTargetID], tblrecommended[Order], "" ), _xlfn.XLOOKUP( A49, tblrecommended[PassiveTargetID], tblrecommended[Order], "" ) ) )} -> 29
A50: building.guild_video_game_arcade@1 | B50: {=_xlfn.XLOOKUP(Checklist!$A50,tblTargets[TargetID],tblTargets[DisplayName])} -> Guild: Video Game Arcade Lv 1 | C50: {=_xlfn.XLOOKUP( A50, tblTargetStatus[TargetID], tblTargetStatus[successors], "" )} | D50: {=_xlfn.XLOOKUP( A50, tblTargets[TargetID], tblTargets[TargetType], "" )} -> BUILDING | E50: {=_xlfn.XLOOKUP( A50, tblTargetStatus[TargetID], tblTargetStatus[ChainAwareStatus], "" )} -> BLOCKED | G50: FALSE | H50: {=_xlfn.XLOOKUP( A50, tblTargetStatus[TargetID], tblTargetStatus[TargetFunded], "" )} -> FALSE | I50: {=IF( D50<>"BUILDING", "", IF( Player!$H$1="Active", _xlfn.XLOOKUP( A50, tblrecommended[ActiveTargetID], tblrecommended[Order], "" ), _xlfn.XLOOKUP( A50, tblrecommended[PassiveTargetID], tblrecommended[Order], "" ) ) )}
A51: building.laboratory@1 | B51: {=_xlfn.XLOOKUP(Checklist!$A51,tblTargets[TargetID],tblTargets[DisplayName])} -> Laboratory Lv 1 | C51: {=_xlfn.XLOOKUP( A51, tblTargetStatus[TargetID], tblTargetStatus[successors], "" )} -> Laboratory Lv 2 | D51: {=_xlfn.XLOOKUP( A51, tblTargets[TargetID], tblTargets[TargetType], "" )} -> BUILDING | E51: {=_xlfn.XLOOKUP( A51, tblTargetStatus[TargetID], tblTargetStatus[ChainAwareStatus], "" )} -> BLOCKED | F51: 66 | G51: FALSE | H51: {=_xlfn.XLOOKUP( A51, tblTargetStatus[TargetID], tblTargetStatus[TargetFunded], "" )} -> FALSE | I51: {=IF( D51<>"BUILDING", "", IF( Player!$H$1="Active", _xlfn.XLOOKUP( A51, tblrecommended[ActiveTargetID], tblrecommended[Order], "" ), _xlfn.XLOOKUP( A51, tblrecommended[PassiveTargetID], tblrecommended[Order], "" ) ) )} -> 66
A52: building.laboratory@2 | B52: {=_xlfn.XLOOKUP(Checklist!$A52,tblTargets[TargetID],tblTargets[DisplayName])} -> Laboratory Lv 2 | C52: {=_xlfn.XLOOKUP( A52, tblTargetStatus[TargetID], tblTargetStatus[successors], "" )} -> Laboratory Lv 3 | D52: {=_xlfn.XLOOKUP( A52, tblTargets[TargetID], tblTargets[TargetType], "" )} -> BUILDING | E52: {=_xlfn.XLOOKUP( A52, tblTargetStatus[TargetID], tblTargetStatus[ChainAwareStatus], "" )} -> BLOCKED | F52: 67 | G52: FALSE | H52: {=_xlfn.XLOOKUP( A52, tblTargetStatus[TargetID], tblTargetStatus[TargetFunded], "" )} -> FALSE | I52: {=IF( D52<>"BUILDING", "", IF( Player!$H$1="Active", _xlfn.XLOOKUP( A52, tblrecommended[ActiveTargetID], tblrecommended[Order], "" ), _xlfn.XLOOKUP( A52, tblrecommended[PassiveTargetID], tblrecommended[Order], "" ) ) )} -> 67
A53: building.laboratory@3 | B53: {=_xlfn.XLOOKUP(Checklist!$A53,tblTargets[TargetID],tblTargets[DisplayName])} -> Laboratory Lv 3 | C53: {=_xlfn.XLOOKUP( A53, tblTargetStatus[TargetID], tblTargetStatus[successors], "" )} -> Laboratory Lv 4 | D53: {=_xlfn.XLOOKUP( A53, tblTargets[TargetID], tblTargets[TargetType], "" )} -> BUILDING | E53: {=_xlfn.XLOOKUP( A53, tblTargetStatus[TargetID], tblTargetStatus[ChainAwareStatus], "" )} -> BLOCKED | F53: 68 | G53: FALSE | H53: {=_xlfn.XLOOKUP( A53, tblTargetStatus[TargetID], tblTargetStatus[TargetFunded], "" )} -> FALSE | I53: {=IF( D53<>"BUILDING", "", IF( Player!$H$1="Active", _xlfn.XLOOKUP( A53, tblrecommended[ActiveTargetID], tblrecommended[Order], "" ), _xlfn.XLOOKUP( A53, tblrecommended[PassiveTargetID], tblrecommended[Order], "" ) ) )} -> 68
A54: building.laboratory@4 | B54: {=_xlfn.XLOOKUP(Checklist!$A54,tblTargets[TargetID],tblTargets[DisplayName])} -> Laboratory Lv 4 | C54: {=_xlfn.XLOOKUP( A54, tblTargetStatus[TargetID], tblTargetStatus[successors], "" )} -> Laboratory Lv 5 | D54: {=_xlfn.XLOOKUP( A54, tblTargets[TargetID], tblTargets[TargetType], "" )} -> BUILDING | E54: {=_xlfn.XLOOKUP( A54, tblTargetStatus[TargetID], tblTargetStatus[ChainAwareStatus], "" )} -> BLOCKED | F54: 75 | G54: FALSE | H54: {=_xlfn.XLOOKUP( A54, tblTargetStatus[TargetID], tblTargetStatus[TargetFunded], "" )} -> FALSE | I54: {=IF( D54<>"BUILDING", "", IF( Player!$H$1="Active", _xlfn.XLOOKUP( A54, tblrecommended[ActiveTargetID], tblrecommended[Order], "" ), _xlfn.XLOOKUP( A54, tblrecommended[PassiveTargetID], tblrecommended[Order], "" ) ) )} -> 75
A55: building.laboratory@5 | B55: {=_xlfn.XLOOKUP(Checklist!$A55,tblTargets[TargetID],tblTargets[DisplayName])} -> Laboratory Lv 5 | C55: {=_xlfn.XLOOKUP( A55, tblTargetStatus[TargetID], tblTargetStatus[successors], "" )} -> Laboratory maxed, Ahead of Time Chapter 1 Finished | D55: {=_xlfn.XLOOKUP( A55, tblTargets[TargetID], tblTargets[TargetType], "" )} -> BUILDING | E55: {=_xlfn.XLOOKUP( A55, tblTargetStatus[TargetID], tblTargetStatus[ChainAwareStatus], "" )} -> BLOCKED | F55: 76 | G55: FALSE | H55: {=_xlfn.XLOOKUP( A55, tblTargetStatus[TargetID], tblTargetStatus[TargetFunded], "" )} -> FALSE | I55: {=IF( D55<>"BUILDING", "", IF( Player!$H$1="Active", _xlfn.XLOOKUP( A55, tblrecommended[ActiveTargetID], tblrecommended[Order], "" ), _xlfn.XLOOKUP( A55, tblrecommended[PassiveTargetID], tblrecommended[Order], "" ) ) )} -> 76
A56: building.laboratory_data_center@1 | B56: {=_xlfn.XLOOKUP(Checklist!$A56,tblTargets[TargetID],tblTargets[DisplayName])} -> Laboratory: Data Center Lv 1 | C56: {=_xlfn.XLOOKUP( A56, tblTargetStatus[TargetID], tblTargetStatus[successors], "" )} -> Laboratory: Data Center maxed, Ahead of Time Chapter 5 Finished | D56: {=_xlfn.XLOOKUP( A56, tblTargets[TargetID], tblTargets[TargetType], "" )} -> BUILDING | E56: {=_xlfn.XLOOKUP( A56, tblTargetStatus[TargetID], tblTargetStatus[ChainAwareStatus], "" )} -> BLOCKED | G56: FALSE | H56: {=_xlfn.XLOOKUP( A56, tblTargetStatus[TargetID], tblTargetStatus[TargetFunded], "" )} -> FALSE | I56: {=IF( D56<>"BUILDING", "", IF( Player!$H$1="Active", _xlfn.XLOOKUP( A56, tblrecommended[ActiveTargetID], tblrecommended[Order], "" ), _xlfn.XLOOKUP( A56, tblrecommended[PassiveTargetID], tblrecommended[Order], "" ) ) )}
...

Sheet cost checklist
A1: RequirementID | B1: TargetID | C1: DisplayName | D1: TargetType | E1: ResourceID | F1: PaymentSlot | G1: QuantityRequired | H1: Sort | I1: TargetCompleted | J1: PlayerPaid | R1: =IFERROR(__xludf.DUMMYFUNCTION("SORT( UNIQUE( FILTER( E2:E2011, (J2:J2011=FALSE)* (I2:I2011=""READY"") ) ) )"),"coin") -> coin
A2: cost.building.airship@1.chemicals.1 | B2: =IFERROR(__xludf.DUMMYFUNCTION("REGEXREPLACE( REGEXREPLACE(A2,""^cost\."",""""), ""\.[^.]+\.[^.]+$"", """" )"),"building.airship@1") -> building.airship@1 | C2: {=_xlfn.XLOOKUP( B2, tblTargets[TargetID], tblTargets[DisplayName], "" )} -> Airship Lv 1 | D2: {=_xlfn.XLOOKUP( B2, tblTargets[TargetID], tblTargets[TargetType], "" )} -> BUILDING | E2: chemicals | F2: 1 | G2: {=_xlfn.XLOOKUP( A2, tblCost[RequirementID], tblCost[QuantityRequired], "" )} -> 200 | H2: {=IF( OR( LEFT(B2,15)="state.character", RIGHT(B2,6)=".maxed" ), 0, LET( sort, _xlfn.XLOOKUP( B2, tblChecklist[TargetID], tblChecklist[PlayerSort], 0 ), IF(sort=0,500,sort) ) )} -> 44 | I2: {=_xlfn.XLOOKUP( B2, tblTargetStatus[TargetID], tblTargetStatus[Status], "" )} -> BLOCKED | J2: FALSE | R2: =IFERROR(__xludf.DUMMYFUNCTION("""COMPUTED_VALUE"""),"ruby") -> ruby
A3: cost.building.airship@1.coin.1 | B3: =IFERROR(__xludf.DUMMYFUNCTION("REGEXREPLACE( REGEXREPLACE(A3,""^cost\."",""""), ""\.[^.]+\.[^.]+$"", """" )"),"building.airship@1") -> building.airship@1 | C3: {=_xlfn.XLOOKUP( B3, tblTargets[TargetID], tblTargets[DisplayName], "" )} -> Airship Lv 1 | D3: {=_xlfn.XLOOKUP( B3, tblTargets[TargetID], tblTargets[TargetType], "" )} -> BUILDING | E3: coin | F3: 1 | G3: {=_xlfn.XLOOKUP( A3, tblCost[RequirementID], tblCost[QuantityRequired], "" )} -> 2000 | H3: {=IF( OR( LEFT(B3,15)="state.character", RIGHT(B3,6)=".maxed" ), 0, LET( sort, _xlfn.XLOOKUP( B3, tblChecklist[TargetID], tblChecklist[PlayerSort], 0 ), IF(sort=0,500,sort) ) )} -> 44 | I3: {=_xlfn.XLOOKUP( B3, tblTargetStatus[TargetID], tblTargetStatus[Status], "" )} -> BLOCKED | J3: FALSE | R3: =IFERROR(__xludf.DUMMYFUNCTION("""COMPUTED_VALUE"""),"stone") -> stone
A4: cost.building.airship@1.miron.1 | B4: =IFERROR(__xludf.DUMMYFUNCTION("REGEXREPLACE( REGEXREPLACE(A4,""^cost\."",""""), ""\.[^.]+\.[^.]+$"", """" )"),"building.airship@1") -> building.airship@1 | C4: {=_xlfn.XLOOKUP( B4, tblTargets[TargetID], tblTargets[DisplayName], "" )} -> Airship Lv 1 | D4: {=_xlfn.XLOOKUP( B4, tblTargets[TargetID], tblTargets[TargetType], "" )} -> BUILDING | E4: miron | F4: 1 | G4: {=_xlfn.XLOOKUP( A4, tblCost[RequirementID], tblCost[QuantityRequired], "" )} -> 50 | H4: {=IF( OR( LEFT(B4,15)="state.character", RIGHT(B4,6)=".maxed" ), 0, LET( sort, _xlfn.XLOOKUP( B4, tblChecklist[TargetID], tblChecklist[PlayerSort], 0 ), IF(sort=0,500,sort) ) )} -> 44 | I4: {=_xlfn.XLOOKUP( B4, tblTargetStatus[TargetID], tblTargetStatus[Status], "" )} -> BLOCKED | J4: FALSE | R4: =IFERROR(__xludf.DUMMYFUNCTION("""COMPUTED_VALUE"""),"wood") -> wood
A5: cost.building.airship@1.page.1 | B5: =IFERROR(__xludf.DUMMYFUNCTION("REGEXREPLACE( REGEXREPLACE(A5,""^cost\."",""""), ""\.[^.]+\.[^.]+$"", """" )"),"building.airship@1") -> building.airship@1 | C5: {=_xlfn.XLOOKUP( B5, tblTargets[TargetID], tblTargets[DisplayName], "" )} -> Airship Lv 1 | D5: {=_xlfn.XLOOKUP( B5, tblTargets[TargetID], tblTargets[TargetType], "" )} -> BUILDING | E5: page | F5: 1 | G5: {=_xlfn.XLOOKUP( A5, tblCost[RequirementID], tblCost[QuantityRequired], "" )} -> 40 | H5: {=IF( OR( LEFT(B5,15)="state.character", RIGHT(B5,6)=".maxed" ), 0, LET( sort, _xlfn.XLOOKUP( B5, tblChecklist[TargetID], tblChecklist[PlayerSort], 0 ), IF(sort=0,500,sort) ) )} -> 44 | I5: {=_xlfn.XLOOKUP( B5, tblTargetStatus[TargetID], tblTargetStatus[Status], "" )} -> BLOCKED | J5: FALSE
A6: cost.building.airship@1.reagent.1 | B6: =IFERROR(__xludf.DUMMYFUNCTION("REGEXREPLACE( REGEXREPLACE(A6,""^cost\."",""""), ""\.[^.]+\.[^.]+$"", """" )"),"building.airship@1") -> building.airship@1 | C6: {=_xlfn.XLOOKUP( B6, tblTargets[TargetID], tblTargets[DisplayName], "" )} -> Airship Lv 1 | D6: {=_xlfn.XLOOKUP( B6, tblTargets[TargetID], tblTargets[TargetType], "" )} -> BUILDING | E6: reagent | F6: 1 | G6: {=_xlfn.XLOOKUP( A6, tblCost[RequirementID], tblCost[QuantityRequired], "" )} -> 20 | H6: {=IF( OR( LEFT(B6,15)="state.character", RIGHT(B6,6)=".maxed" ), 0, LET( sort, _xlfn.XLOOKUP( B6, tblChecklist[TargetID], tblChecklist[PlayerSort], 0 ), IF(sort=0,500,sort) ) )} -> 44 | I6: {=_xlfn.XLOOKUP( B6, tblTargetStatus[TargetID], tblTargetStatus[Status], "" )} -> BLOCKED | J6: FALSE
A7: cost.building.airship@1.ruby.1 | B7: =IFERROR(__xludf.DUMMYFUNCTION("REGEXREPLACE( REGEXREPLACE(A7,""^cost\."",""""), ""\.[^.]+\.[^.]+$"", """" )"),"building.airship@1") -> building.airship@1 | C7: {=_xlfn.XLOOKUP( B7, tblTargets[TargetID], tblTargets[DisplayName], "" )} -> Airship Lv 1 | D7: {=_xlfn.XLOOKUP( B7, tblTargets[TargetID], tblTargets[TargetType], "" )} -> BUILDING | E7: ruby | F7: 1 | G7: {=_xlfn.XLOOKUP( A7, tblCost[RequirementID], tblCost[QuantityRequired], "" )} -> 10 | H7: {=IF( OR( LEFT(B7,15)="state.character", RIGHT(B7,6)=".maxed" ), 0, LET( sort, _xlfn.XLOOKUP( B7, tblChecklist[TargetID], tblChecklist[PlayerSort], 0 ), IF(sort=0,500,sort) ) )} -> 44 | I7: {=_xlfn.XLOOKUP( B7, tblTargetStatus[TargetID], tblTargetStatus[Status], "" )} -> BLOCKED | J7: FALSE
A8: cost.building.airship@1.silk.1 | B8: =IFERROR(__xludf.DUMMYFUNCTION("REGEXREPLACE( REGEXREPLACE(A8,""^cost\."",""""), ""\.[^.]+\.[^.]+$"", """" )"),"building.airship@1") -> building.airship@1 | C8: {=_xlfn.XLOOKUP( B8, tblTargets[TargetID], tblTargets[DisplayName], "" )} -> Airship Lv 1 | D8: {=_xlfn.XLOOKUP( B8, tblTargets[TargetID], tblTargets[TargetType], "" )} -> BUILDING | E8: silk | F8: 1 | G8: {=_xlfn.XLOOKUP( A8, tblCost[RequirementID], tblCost[QuantityRequired], "" )} -> 120 | H8: {=IF( OR( LEFT(B8,15)="state.character", RIGHT(B8,6)=".maxed" ), 0, LET( sort, _xlfn.XLOOKUP( B8, tblChecklist[TargetID], tblChecklist[PlayerSort], 0 ), IF(sort=0,500,sort) ) )} -> 44 | I8: {=_xlfn.XLOOKUP( B8, tblTargetStatus[TargetID], tblTargetStatus[Status], "" )} -> BLOCKED | J8: FALSE
A9: cost.building.airship@1.thread.1 | B9: =IFERROR(__xludf.DUMMYFUNCTION("REGEXREPLACE( REGEXREPLACE(A9,""^cost\."",""""), ""\.[^.]+\.[^.]+$"", """" )"),"building.airship@1") -> building.airship@1 | C9: {=_xlfn.XLOOKUP( B9, tblTargets[TargetID], tblTargets[DisplayName], "" )} -> Airship Lv 1 | D9: {=_xlfn.XLOOKUP( B9, tblTargets[TargetID], tblTargets[TargetType], "" )} -> BUILDING | E9: thread | F9: 1 | G9: {=_xlfn.XLOOKUP( A9, tblCost[RequirementID], tblCost[QuantityRequired], "" )} -> 20 | H9: {=IF( OR( LEFT(B9,15)="state.character", RIGHT(B9,6)=".maxed" ), 0, LET( sort, _xlfn.XLOOKUP( B9, tblChecklist[TargetID], tblChecklist[PlayerSort], 0 ), IF(sort=0,500,sort) ) )} -> 44 | I9: {=_xlfn.XLOOKUP( B9, tblTargetStatus[TargetID], tblTargetStatus[Status], "" )} -> BLOCKED | J9: FALSE
A10: cost.building.airship@2.coin.1 | B10: =IFERROR(__xludf.DUMMYFUNCTION("REGEXREPLACE( REGEXREPLACE(A10,""^cost\."",""""), ""\.[^.]+\.[^.]+$"", """" )"),"building.airship@2") -> building.airship@2 | C10: {=_xlfn.XLOOKUP( B10, tblTargets[TargetID], tblTargets[DisplayName], "" )} -> Airship Lv 2 | D10: {=_xlfn.XLOOKUP( B10, tblTargets[TargetID], tblTargets[TargetType], "" )} -> BUILDING | E10: coin | F10: 1 | G10: {=_xlfn.XLOOKUP( A10, tblCost[RequirementID], tblCost[QuantityRequired], "" )} -> 3000 | H10: {=IF( OR( LEFT(B10,15)="state.character", RIGHT(B10,6)=".maxed" ), 0, LET( sort, _xlfn.XLOOKUP( B10, tblChecklist[TargetID], tblChecklist[PlayerSort], 0 ), IF(sort=0,500,sort) ) )} -> 45 | I10: {=_xlfn.XLOOKUP( B10, tblTargetStatus[TargetID], tblTargetStatus[Status], "" )} -> BLOCKED | J10: FALSE
A11: cost.building.airship@2.fan.1 | B11: =IFERROR(__xludf.DUMMYFUNCTION("REGEXREPLACE( REGEXREPLACE(A11,""^cost\."",""""), ""\.[^.]+\.[^.]+$"", """" )"),"building.airship@2") -> building.airship@2 | C11: {=_xlfn.XLOOKUP( B11, tblTargets[TargetID], tblTargets[DisplayName], "" )} -> Airship Lv 2 | D11: {=_xlfn.XLOOKUP( B11, tblTargets[TargetID], tblTargets[TargetType], "" )} -> BUILDING | E11: fan | F11: 1 | G11: {=_xlfn.XLOOKUP( A11, tblCost[RequirementID], tblCost[QuantityRequired], "" )} -> 50 | H11: {=IF( OR( LEFT(B11,15)="state.character", RIGHT(B11,6)=".maxed" ), 0, LET( sort, _xlfn.XLOOKUP( B11, tblChecklist[TargetID], tblChecklist[PlayerSort], 0 ), IF(sort=0,500,sort) ) )} -> 45 | I11: {=_xlfn.XLOOKUP( B11, tblTargetStatus[TargetID], tblTargetStatus[Status], "" )} -> BLOCKED | J11: FALSE
A12: cost.building.airship@2.gears.1 | B12: =IFERROR(__xludf.DUMMYFUNCTION("REGEXREPLACE( REGEXREPLACE(A12,""^cost\."",""""), ""\.[^.]+\.[^.]+$"", """" )"),"building.airship@2") -> building.airship@2 | C12: {=_xlfn.XLOOKUP( B12, tblTargets[TargetID], tblTargets[DisplayName], "" )} -> Airship Lv 2 | D12: {=_xlfn.XLOOKUP( B12, tblTargets[TargetID], tblTargets[TargetType], "" )} -> BUILDING | E12: gears | F12: 1 | G12: {=_xlfn.XLOOKUP( A12, tblCost[RequirementID], tblCost[QuantityRequired], "" )} -> 20 | H12: {=IF( OR( LEFT(B12,15)="state.character", RIGHT(B12,6)=".maxed" ), 0, LET( sort, _xlfn.XLOOKUP( B12, tblChecklist[TargetID], tblChecklist[PlayerSort], 0 ), IF(sort=0,500,sort) ) )} -> 45 | I12: {=_xlfn.XLOOKUP( B12, tblTargetStatus[TargetID], tblTargetStatus[Status], "" )} -> BLOCKED | J12: FALSE
A13: cost.building.airship@2.plank.1 | B13: =IFERROR(__xludf.DUMMYFUNCTION("REGEXREPLACE( REGEXREPLACE(A13,""^cost\."",""""), ""\.[^.]+\.[^.]+$"", """" )"),"building.airship@2") -> building.airship@2 | C13: {=_xlfn.XLOOKUP( B13, tblTargets[TargetID], tblTargets[DisplayName], "" )} -> Airship Lv 2 | D13: {=_xlfn.XLOOKUP( B13, tblTargets[TargetID], tblTargets[TargetType], "" )} -> BUILDING | E13: plank | F13: 1 | G13: {=_xlfn.XLOOKUP( A13, tblCost[RequirementID], tblCost[QuantityRequired], "" )} -> 60 | H13: {=IF( OR( LEFT(B13,15)="state.character", RIGHT(B13,6)=".maxed" ), 0, LET( sort, _xlfn.XLOOKUP( B13, tblChecklist[TargetID], tblChecklist[PlayerSort], 0 ), IF(sort=0,500,sort) ) )} -> 45 | I13: {=_xlfn.XLOOKUP( B13, tblTargetStatus[TargetID], tblTargetStatus[Status], "" )} -> BLOCKED | J13: FALSE
A14: cost.building.airship@2.ruby.1 | B14: =IFERROR(__xludf.DUMMYFUNCTION("REGEXREPLACE( REGEXREPLACE(A14,""^cost\."",""""), ""\.[^.]+\.[^.]+$"", """" )"),"building.airship@2") -> building.airship@2 | C14: {=_xlfn.XLOOKUP( B14, tblTargets[TargetID], tblTargets[DisplayName], "" )} -> Airship Lv 2 | D14: {=_xlfn.XLOOKUP( B14, tblTargets[TargetID], tblTargets[TargetType], "" )} -> BUILDING | E14: ruby | F14: 1 | G14: {=_xlfn.XLOOKUP( A14, tblCost[RequirementID], tblCost[QuantityRequired], "" )} -> 12 | H14: {=IF( OR( LEFT(B14,15)="state.character", RIGHT(B14,6)=".maxed" ), 0, LET( sort, _xlfn.XLOOKUP( B14, tblChecklist[TargetID], tblChecklist[PlayerSort], 0 ), IF(sort=0,500,sort) ) )} -> 45 | I14: {=_xlfn.XLOOKUP( B14, tblTargetStatus[TargetID], tblTargetStatus[Status], "" )} -> BLOCKED | J14: FALSE
A15: cost.building.airship@2.silk.1 | B15: =IFERROR(__xludf.DUMMYFUNCTION("REGEXREPLACE( REGEXREPLACE(A15,""^cost\."",""""), ""\.[^.]+\.[^.]+$"", """" )"),"building.airship@2") -> building.airship@2 | C15: {=_xlfn.XLOOKUP( B15, tblTargets[TargetID], tblTargets[DisplayName], "" )} -> Airship Lv 2 | D15: {=_xlfn.XLOOKUP( B15, tblTargets[TargetID], tblTargets[TargetType], "" )} -> BUILDING | E15: silk | F15: 1 | G15: {=_xlfn.XLOOKUP( A15, tblCost[RequirementID], tblCost[QuantityRequired], "" )} -> 100 | H15: {=IF( OR( LEFT(B15,15)="state.character", RIGHT(B15,6)=".maxed" ), 0, LET( sort, _xlfn.XLOOKUP( B15, tblChecklist[TargetID], tblChecklist[PlayerSort], 0 ), IF(sort=0,500,sort) ) )} -> 45 | I15: {=_xlfn.XLOOKUP( B15, tblTargetStatus[TargetID], tblTargetStatus[Status], "" )} -> BLOCKED | J15: FALSE
A16: cost.building.airship@2.thread.1 | B16: =IFERROR(__xludf.DUMMYFUNCTION("REGEXREPLACE( REGEXREPLACE(A16,""^cost\."",""""), ""\.[^.]+\.[^.]+$"", """" )"),"building.airship@2") -> building.airship@2 | C16: {=_xlfn.XLOOKUP( B16, tblTargets[TargetID], tblTargets[DisplayName], "" )} -> Airship Lv 2 | D16: {=_xlfn.XLOOKUP( B16, tblTargets[TargetID], tblTargets[TargetType], "" )} -> BUILDING | E16: thread | F16: 1 | G16: {=_xlfn.XLOOKUP( A16, tblCost[RequirementID], tblCost[QuantityRequired], "" )} -> 10 | H16: {=IF( OR( LEFT(B16,15)="state.character", RIGHT(B16,6)=".maxed" ), 0, LET( sort, _xlfn.XLOOKUP( B16, tblChecklist[TargetID], tblChecklist[PlayerSort], 0 ), IF(sort=0,500,sort) ) )} -> 45 | I16: {=_xlfn.XLOOKUP( B16, tblTargetStatus[TargetID], tblTargetStatus[Status], "" )} -> BLOCKED | J16: FALSE
A17: cost.building.alchemists_hut@1.coin.1 | B17: =IFERROR(__xludf.DUMMYFUNCTION("REGEXREPLACE( REGEXREPLACE(A17,""^cost\."",""""), ""\.[^.]+\.[^.]+$"", """" )"),"building.alchemists_hut@1") -> building.alchemists_hut@1 | C17: {=_xlfn.XLOOKUP( B17, tblTargets[TargetID], tblTargets[DisplayName], "" )} -> Alchemist's Hut Lv 1 | D17: {=_xlfn.XLOOKUP( B17, tblTargets[TargetID], tblTargets[TargetType], "" )} -> BUILDING | E17: coin | F17: 1 | G17: {=_xlfn.XLOOKUP( A17, tblCost[RequirementID], tblCost[QuantityRequired], "" )} -> 140 | H17: {=IF( OR( LEFT(B17,15)="state.character", RIGHT(B17,6)=".maxed" ), 0, LET( sort, _xlfn.XLOOKUP( B17, tblChecklist[TargetID], tblChecklist[PlayerSort], 0 ), IF(sort=0,500,sort) ) )} -> 4 | I17: {=_xlfn.XLOOKUP( B17, tblTargetStatus[TargetID], tblTargetStatus[Status], "" )} -> BLOCKED | J17: FALSE
A18: cost.building.alchemists_hut@1.ruby.1 | B18: =IFERROR(__xludf.DUMMYFUNCTION("REGEXREPLACE( REGEXREPLACE(A18,""^cost\."",""""), ""\.[^.]+\.[^.]+$"", """" )"),"building.alchemists_hut@1") -> building.alchemists_hut@1 | C18: {=_xlfn.XLOOKUP( B18, tblTargets[TargetID], tblTargets[DisplayName], "" )} -> Alchemist's Hut Lv 1 | D18: {=_xlfn.XLOOKUP( B18, tblTargets[TargetID], tblTargets[TargetType], "" )} -> BUILDING | E18: ruby | F18: 1 | G18: {=_xlfn.XLOOKUP( A18, tblCost[RequirementID], tblCost[QuantityRequired], "" )} -> 1 | H18: {=IF( OR( LEFT(B18,15)="state.character", RIGHT(B18,6)=".maxed" ), 0, LET( sort, _xlfn.XLOOKUP( B18, tblChecklist[TargetID], tblChecklist[PlayerSort], 0 ), IF(sort=0,500,sort) ) )} -> 4 | I18: {=_xlfn.XLOOKUP( B18, tblTargetStatus[TargetID], tblTargetStatus[Status], "" )} -> BLOCKED | J18: FALSE
A19: cost.building.alchemists_hut@1.stone.1 | B19: =IFERROR(__xludf.DUMMYFUNCTION("REGEXREPLACE( REGEXREPLACE(A19,""^cost\."",""""), ""\.[^.]+\.[^.]+$"", """" )"),"building.alchemists_hut@1") -> building.alchemists_hut@1 | C19: {=_xlfn.XLOOKUP( B19, tblTargets[TargetID], tblTargets[DisplayName], "" )} -> Alchemist's Hut Lv 1 | D19: {=_xlfn.XLOOKUP( B19, tblTargets[TargetID], tblTargets[TargetType], "" )} -> BUILDING | E19: stone | F19: 1 | G19: {=_xlfn.XLOOKUP( A19, tblCost[RequirementID], tblCost[QuantityRequired], "" )} -> 70 | H19: {=IF( OR( LEFT(B19,15)="state.character", RIGHT(B19,6)=".maxed" ), 0, LET( sort, _xlfn.XLOOKUP( B19, tblChecklist[TargetID], tblChecklist[PlayerSort], 0 ), IF(sort=0,500,sort) ) )} -> 4 | I19: {=_xlfn.XLOOKUP( B19, tblTargetStatus[TargetID], tblTargetStatus[Status], "" )} -> BLOCKED | J19: FALSE
